Workbook

Sheet all
A1: 乘车 | B1: 序号 | C1: 日期 | D1: 出发地 | E1: 目的地 | F1: 车次 | G1: 类别 | H1: 车型 | I1: 坐席 | J1: 座位号 | K1: 价格 | L1: 里程 | M1: 每公里单价 | N1: 时速 | O1: 出发时间 | P1: 到站时间 | Q1: 时长 | R1: 车次担当局 | S1: 客运段 | T1: 备注 | U1: 出发 | V1: 到达 | W1: 总里程 | X1: 区间与里程 | Y1: 其他 | AE1: 牵引
A2: 次数 | B2: 0 | K2: =SUM(K$3:K$9999) -> 5509.5 | L2: =SUM(L$3:L$9999) -> 11831 | M2: =K2/L2 -> 0.46568337 | N2: =L2/(Q2*24) -> 119.48494 | O2: =AVERAGE(O3:O1000) -> 0.58911385 | P2: =AVERAGE(P3:P1000) -> 0.63300078 | Q2: =SUM(Q$3:Q$9999) -> 4.1256944 | R2: =Q2/COUNT(A3:A1000) -> 0.060671977
A3: 1 | B3: 1 | C3: 44734 | D3: 大理 | E3: 昆明 | F3: D8732 | G3: 动车 | H3: CRH2A | I3: 二等 | K3: 145 | L3: 328 | M3: =K3/L3 -> 0.44207317 | N3: =L3/(Q3*24) -> 140.57143 | O3: 0.86458333 | P3: 0.95208333 | Q3: 0.097222222 | R3: 昆明局 | S3: 昆明段 | W3: 328km | X3: 大理-楚大线175km-广通北-广昆线广温段121km-温泉-成昆铁路元昆段32km-昆明 | AD3: =3000*Q3 -> 291.66667
A4: 2 | B4: 2 | C4: 44774 | D4: 东莞 | E4: 厦门 | F4: D2385 | G4: 动车 | H4: CRH1A-A | I4: 二等 | J4: 04车 | K4: 149 | L4: 575 | M4: =K4/L4 -> 0.25913043 | N4: =L4/(Q4*24) -> 138.55422 | O4: 0.38888889 | P4: 0.56180556 | Q4: =P4-O4 -> 0.17291667 | R4: 广州局 | S4: 广九段 | T4: 跨 | W4: 575km | X4: 东莞-广九线56km-平湖-平湖联络线8km-李朗所-杭深线485km-前场-鹰厦线26km-厦门 | AD4: =3000*Q4 -> 518.75
A5: 3 | B5: 3 | C5: 44777 | D5: 厦门北 | E5: 东莞 | F5: D3653 | G5: 动车 | H5: CRH1A-A | I5: 二等 | J5: 03车06D | K5: 138 | L5: 562 | M5: =K5/L5 -> 0.2455516 | N5: =L5/(Q5*24) -> 142.88136 | O5: 0.58125 | P5: 0.74513889 | Q5: =P5-O5 -> 0.16388889 | R5: 南昌局 | S5: 福州段 | T5: 跨 | W5: 526km | X5: 厦门北-杭深线498km-李朗所-平湖联络线8km-平湖-广九线56km-东莞 | AD5: =3000*Q5 -> 491.66667
A6: 4 | B6: 4 | C6: 44788 | D6: 东莞 | E6: 东莞南 | F6: D3309 | G6: 动车 | H6: CRH1A-A | I6: 二等 | J6: 04车10F | K6: 45 | L6: 39 | M6: =K6/L6 -> 1.1538462 | N6: =L6/(Q6*24) -> 106.36364 | O6: 0.33680556 | P6: 0.35208333 | Q6: =P6-O6 -> 0.015277778 | R6: 广州局 | S6: 广九段 | T6: 跨 | W6: 39km | X6: 东莞-广九线37km-塘厦所-莞塘深联络线2km-东莞南 | AD6: =3000*Q6 -> 45.833333
A7: 5 | B7: 5 | C7: 44788 | D7: 东莞南 | E7: 东莞 | F7: D7122 | G7: 动车 | H7: CRH1A-A | I7: 二等 | J7: 03车 | K7: 42 | L7: 39 | M7: =K7/L7 -> 1.0769231 | N7: =L7/(Q7*24) -> 111.42857 | O7: 0.91180556 | P7: 0.92638889 | Q7: =P7-O7 -> 0.014583333 | R7: 广州局 | S7: 广九段 | W7: 39km | X7: 东莞南-莞塘深联络线2km-塘厦所-广九线37km-东莞 | AD7: =3000*Q7 -> 43.75
A8: 6 | B8: 6 | C8: 44835 | D8: 深圳北 | E8: 东莞 | F8: D7150 | G8: 动车 | H8: CRH1A-A | I8: 二等 | K8: 48 | L8: 74 | M8: =K8/L8 -> 0.64864865 | N8: =L8/(Q8*24) -> 111 | O8: 0.51458333 | P8: 0.54236111 | Q8: =P8-O8 -> 0.027777778 | R8: 广州局 | S8: 广九段 | W8: 74km | X8: 深圳北-广深港高速线16km-光明城-京港高铁赣深段19km-东莞南-莞塘深联络线2km-塘厦所-广九线37km-东莞 | AD8: =3000*Q8 -> 83.333333
A9: 7 | B9: 7 | C9: 44841 | D9: 东莞 | E9: 深圳北 | F9: D7149 | G9: 动车 | H9: CRH1A-A | I9: 二等 | J9: 08车09B | K9: 50 | L9: 74 | M9: =K9/L9 -> 0.67567568 | N9: =L9/(Q9*24) -> 82.222222 | O9: 0.60208333 | P9: 0.63958333 | Q9: =P9-O9 -> 0.0375 | R9: 广州局 | S9: 广九段 | W9: 74km | X9: 东莞-广九线37km-塘厦所-莞塘深联络线2km-东莞南-京港高铁赣深段19km-光明城-广深港高速线16km-深圳北 | AD9: =3000*Q9 -> 112.5
A10: 8 | B10: 8 | C10: 44907 | D10: 深圳北 | E10: 东莞 | F10: D3656 | G10: 动车 | H10: CRH2A | I10: 二等 | J10: 08车11F | K10: 54 | L10: 74 | M10: =K10/L10 -> 0.72972973 | N10: =L10/(Q10*24) -> 113.84615 | O10: 0.38888889 | P10: 0.41597222 | Q10: =P10-O10 -> 0.027083333 | R10: 南宁局 | S10: 南宁段 | T10: 跨 | W10: 74km | X10: 深圳北-广深港高速线16km-光明城-京港高铁赣深段19km-东莞南-莞塘深联络线2km-塘厦所-广九线37km-东莞 | Y10: 重联 | AD10: =3000*Q10 -> 81.25
A11: 9 | B11: 9 | C11: 44965 | D11: 东莞 | E11: 深圳北 | F11: D3309 | G11: 动车 | H11: CRH1A-A | I11: 二等 | J11: 07车03F | K11: 54 | L11: 74 | M11: =K11/L11 -> 0.72972973 | N11: =L11/(Q11*24) -> 92.5 | O11: 0.33680556 | P11: 0.37013889 | Q11: =P11-O11 -> 0.033333333 | R11: 广州局 | S11: 广九段 | T11: 跨 | W11: 74km | X11: 东莞-广九线37km-塘厦所-莞塘深联络线2km-东莞南-京港高铁赣深段19km-光明城-广深港高速线16km-深圳北 | AD11: =3000*Q11 -> 100
A12: 10 | B12: 10 | C12: 45016 | D12: 深圳北 | E12: 东莞 | F12: D7122 | G12: 动车 | H12: CRH1A-A | I12: 二等 | J12: 08车04C | K12: 48 | L12: 74 | M12: =K12/L12 -> 0.64864865 | N12: =L12/(Q12*24) -> 113.84615 | O12: 0.89930556 | P12: 0.92638889 | Q12: =P12-O12 -> 0.027083333 | R12: 广州局 | S12: 广九段 | W12: 74km | X12: 深圳北-广深港高速线16km-光明城-京港高铁赣深段19km-东莞南-莞塘深联络线2km-塘厦所-广九线37km-东莞 | AD12: =3000*Q12 -> 81.25
A13: 11 | B13: 11 | C13: 45045 | D13: 深圳北 | E13: 东莞 | F13: D7146 | G13: 动车 | H13: CRH1A-A | I13: 二等 | J13: 15车03A | K13: 48 | L13: 74 | M13: =K13/L13 -> 0.64864865 | N13: =L13/(Q13*24) -> 111 | O13: 0.92916667 | P13: 0.95694444 | Q13: =P13-O13 -> 0.027777778 | R13: 广州局 | S13: 广九段 | W13: 74km | X13: 深圳北-广深港高速线16km-光明城-京港高铁赣深段19km-东莞南-莞塘深联络线2km-塘厦所-广九线37km-东莞 | AD13: =3000*Q13 -> 83.333333
A14: 12 | B14: 12 | C14: 45049 | D14: 东莞 | E14: 深圳北 | F14: D3309 | G14: 动车 | H14: CRH1A-A | I14: 二等 | J14: 07车13A | K14: 54 | L14: 74 | M14: =K14/L14 -> 0.72972973 | N14: =L14/(Q14*24) -> 92.5 | O14: 0.33680556 | P14: 0.37013889 | Q14: =P14-O14 -> 0.033333333 | R14: 广州局 | S14: 广九段 | T14: 跨 | W14: 74km | X14: 东莞-广九线37km-塘厦所-莞塘深联络线2km-东莞南-京港高铁赣深段19km-光明城-广深港高速线16km-深圳北 | AD14: =3000*Q14 -> 100
A15: 13 | B15: 13 | C15: 45102 | D15: 深圳北 | E15: 惠东南 | F15: D2304 | G15: 动车 | H15: CRH1A-A | I15: 二等 | J15: 08车13F | K15: 39 | L15: 88 | M15: =K15/L15 -> 0.44318182 | N15: =L15/(Q15*24) -> 176 | O15: 0.61319444 | P15: 0.63402778 | Q15: =P15-O15 -> 0.020833333 | R15: 南昌局 | S15: 福州段 | T15: 跨 | W15: 88km | X15: 深圳北-杭深线88km-惠东 | Y15: 重联 | AD15: =3000*Q15 -> 62.5
A16: 14 | B16: 14 | C16: 45104 | D16: 无锡新区 | E16: 苏州 | F16: G7229 | G16: 高铁 | H16: CRH2C | I16: 二等 | J16: 06车19F | K16: 13 | L16: 29 | M16: =K16/L16 -> 0.44827586 | N16: =L16/(Q16*24) -> 158.18182 | O16: 0.59236111 | P16: 0.6 | Q16: =P16-O16 -> 0.0076388889 | R16: 上海局 | S16: 南京段 | W16: 29km | X16: 无锡新区-沪宁高速线29km-苏州 | Y16: 二阶段 | AD16: =3000*Q16 -> 22.916667
A17: 15 | B17: 15 | C17: 45106 | D17: 苏州 | E17: 阳澄湖 | F17: D5665 | G17: 动车 | H17: CRH1B | I17: 二等 | K17: 9 | L17: 25 | M17: =K17/L17 -> 0.36 | N17: =L17/(Q17*24) -> 136.36364 | O17: 0.39513889 | P17: 0.40277778 | Q17: =P17-O17 -> 0.0076388889 | R17: 上海局 | S17: 南京段 | W17: 25km | X17: 苏州-沪宁高速线25km-阳澄湖 | AD17: =3000*Q17 -> 22.916667
A18: 16 | B18: 16 | C18: 45107 | D18: 苏州 | E18: 无锡 | F18: G7232 | G18: 高铁 | H18: CRH2C-2 | I18: 二等 | J18: 01车08D | K18: 21 | L18: 42 | M18: =K18/L18 -> 0.5 | N18: =L18/(Q18*24) -> 96.923077 | O18: 0.36736111 | P18: 0.38541667 | Q18: =P18-O18 -> 0.018055556 | R18: 上海局 | S18: 南京段 | W18: 42km | X18: 苏州-沪宁高速线/京沪线42km-无锡 | AD18: =3000*Q18 -> 54.166667
A19: 17 | B19: 17 | C19: 45107 | D19: 无锡 | E19: 南京 | F19: G7026 | G19: 高铁 | H19: CRH2C | I19: 二等 | J19: 08车09D | K19: 88 | L19: 174 | M19: =K19/L19 -> 0.50574713 | N19: =L19/(Q19*24) -> 163.125 | O19: 0.82291667 | P19: 0.86736111 | Q19: =P19-O19 -> 0.044444444 | R19: 上海局 | S19: 南京段 | W19: 174km | X19: 无锡-京沪线83km-丹阳-沪宁高速线27km-镇江-京沪线64km-南京 | Y19: 重联 | AD19: =3000*Q19 -> 133.33333
A20: 18 | B20: 18 | C20: 45121 | D20: 深圳北 | E20: 长沙南 | F20: G6004 | G20: 高铁 | H20: CRH380B | I20: 二等 | J20: 07车12F | K20: 388.5 | L20: 809 | M20: =K20/L20 -> 0.4802225 | N20: =L20/(Q20*24) -> 234.49275 | O20: 0.38402778 | P20: 0.52777778 | Q20: =P20-O20 -> 0.14375 | R20: 广州局 | S20: 长沙段 | W20: 809km | X20: 深圳北-广深港高速线102km-广州南-京广高铁707km-长沙南 | AB20: 广州南调向 | AD20: =3000*Q20 -> 431.25
A21: 19 | B21: 19 | C21: 45123 | D21: 长沙南 | E21: 深圳北 | F21: G829 | G21: 高铁 | H21: CRH380BL | I21: 二等 | J21: 15车03F | K21: 388.5 | L21: 809 | M21: =K21/L21 -> 0.4802225 | N21: =L21/(Q21*24) -> 219.63801 | O21: 0.80833333 | P21: 0.96180556 | Q21: =P21-O21 -> 0.15347222 | R21: 西安局 | S21: 西安段 | W21: 809km | X21: 长沙南-京广高铁707km-广州南-广深港高速线102km-深圳北 | AD21: =3000*Q21 -> 460.41667
A22: 20 | B22: 20 | C22: 45131 | D22: 深圳北 | E22: 东莞 | F22: D7178 | G22: 动车 | H22: CRH1A-A | I22: 二等 | J22: 04车09A | K22: 45 | L22: 74 | M22: =K22/L22 -> 0.60810811 | N22: =L22/(Q22*24) -> 113.84615 | O22: 0.70486111 | P22: 0.73194444 | Q22: =P22-O22 -> 0.027083333 | R22: 广州局 | S22: 广九段 | W22: 74km | X22: 深圳北-广深港高速线16km-光明城-京港高铁赣深段19km-东莞南-莞塘深联络线2km-塘厦所-广九线37km-东莞 | AD22: =3000*Q22 -> 81.25
A23: 21 | B23: 21 | C23: 45133 | D23: 东莞 | E23: 广州 | F23: C7080 | G23: 城际 | H23: CRH1A | I23: 二等 | J23: 06车02D | K23: 45.5 | L23: 71 | M23: =K23/L23 -> 0.64084507 | N23: =L23/(Q23*24) -> 86.938776 | O23: 0.44375 | P23: 0.47777778 | Q23: =P23-O23 -> 0.034027778 | R23: 广州局 | S23: 广九段 | W23: 71km | X23: 东莞-广九线71km-广州 | AD23: =3000*Q23 -> 102.08333
A24: 22 | B24: 22 | C24: 45133 | D24: 广州 | E24: 阳春 | F24: K837 | G24: 快速 | H24: 25G | I24: 硬卧 | J24: 12车12中 | K24: 91.5 | L24: 246 | M24: =K24/L24 -> 0.37195122 | N24: =L24/(Q24*24) -> 71.304348 | O24: 0.50763889 | P24: 0.65138889 | Q24: =P24-O24 -> 0.14375 | R24: 成都局 | S24: 重庆段 | T24: 跨 | W24: 246km | X24: 广州-广茂线246km-阳春 | AD24: =3000*Q24 -> 431.25
A25: 23 | B25: 23 | C25: 45156 | D25: 阳江 | E25: 江门 | F25: G6086 | G25: 高铁 | H25: CRH380B | I25: 二等 | J25: 08车06F | K25: 88 | L25: 148 | M25: =K25/L25 -> 0.59459459 | N25: =L25/(Q25*24) -> 167.54717 | O25: 0.39305556 | P25: 0.42986111 | Q25: =P25-O25 -> 0.036805556 | R25: 广州局 | S25: 长沙段 | W25: 148km | X25: 阳江-深湛线江湛段148km-江门 | AD25: =3000*Q25 -> 110.41667
B26: 24 | C26: 45156 | D26: 江门 | E26: 深圳北 | F26: G6086 | G26: 高铁 | H26: CRH380B | I26: 无座 | J26: - | K26: 131.5 | L26: 177 | M26: =K26/L26 -> 0.74293785 | N26: =L26/(Q26*24) -> 112.97872 | O26: 0.43125 | P26: 0.49652778 | Q26: =P26-O26 -> 0.065277778 | R26: 广州局 | S26: 长沙段 | W26: 177km | X26: 江门-江门线30km-小榄-广珠城际线45km-广州南-广深港高速线102km-深圳北 | AD26: =3000*Q26 -> 195.83333
A27: 24 | B27: 25 | C27: 45156 | D27: 深圳北 | E27: 东莞 | F27: D7166 | G27: 动车 | H27: CRH1A-A | I27: 二等 | J27: 06车03B | K27: 45 | L27: 74 | M27: =K27/L27 -> 0.60810811 | N27: =L27/(Q27*24) -> 113.84615 | O27: 0.76388889 | P27: 0.79097222 | Q27: =P27-O27 -> 0.027083333 | R27: 广州局 | S27: 广九段 | W27: 74km | X27: 深圳北-广深港高速线16km-光明城-京港高铁赣深段19km-东莞南-莞塘深联络线2km-塘厦所-广九线37km-东莞 | AD27: =3000*Q27 -> 81.25
A28: 25 | B28: 26 | C28: 45163 | D28: 东莞 | E28: 深圳北 | F28: D2321 | G28: 动车 | H28: CRH2A | I28: 二等 | J28: 03车07A | K28: 54 | L28: 74 | M28: =K28/L28 -> 0.72972973 | N28: =L28/(Q28*24) -> 90.612245 | O28: 0.48472222 | P28: 0.51875 | Q28: =P28-O28 -> 0.034027778 | R28: 南昌局 | S28: 南昌段 | T28: 跨 | W28: 74km | X28: 东莞-广九线37km-塘厦所-莞塘深联络线2km-东莞南-京港高铁赣深段19km-光明城-广深港高速线16km-深圳北 | Y28: 重联 | AD28: =3000*Q28 -> 102.08333
A29: 26 | B29: 27 | C29: 45184 | D29: 深圳北 | E29: 东莞 | F29: G6558 | G29: 高铁 | H29: CR300AF | I29: 二等 | J29: 06车15C | K29: 58 | L29: 74 | M29: =K29/L29 -> 0.78378378 | N29: =L29/(Q29*24) -> 113.84615 | O29: 0.6125 | P29: 0.63958333 | Q29: =P29-O29 -> 0.027083333 | R29: 广州局 | S29: 广九段 | T29: 港 | W29: 74km | X29: 深圳北-广深港高速线16km-光明城-京港高铁赣深段19km-东莞南-莞塘深联络线2km-塘厦所-广九线37km-东莞 | AD29: =3000*Q29 -> 81.25
A30: 27 | B30: 28 | C30: 45186 | D30: 东莞 | E30: 深圳北 | F30: G6547 | G30: 高铁 | H30: CR300AF | I30: 二等 | J30: 03车11F | K30: 58 | L30: 74 | M30: =K30/L30 -> 0.78378378 | N30: =L30/(Q30*24) -> 82.222222 | O30: 0.59444444 | P30: 0.63194444 | Q30: =P30-O30 -> 0.0375 | R30: 广州局 | S30: 广九段 | T30: 港 | W30: 74km | X30: 东莞-广九线37km-塘厦所-莞塘深联络线2km-东莞南-京港高铁赣深段19km-光明城-广深港高速线16km-深圳北 | AD30: =3000*Q30 -> 112.5
A31: 28 | B31: 29 | C31: 45197 | D31: 深圳北 | E31: 虎门 | F31: G1624 | G31: 高铁 | H31: CR400AF-A | I31: 二等 | J31: 06车10F | K31: 39.5 | L31: 52 | M31: =K31/L31 -> 0.75961538 | N31: =L31/(Q31*24) -> 183.52941 | O31: 0.88472222 | P31: 0.89652778 | Q31: =P31-O31 -> 0.011805556 | R31: 广州局 | S31: 广州段 | T31: 跨 | W31: 52km | X31: 深圳北-广深港高速线52km-虎门 | AD31: =3000*Q31 -> 35.416667
A32: 29 | B32: 30 | C32: 45203 | D32: 阳春 | E32: 茂名 | F32: T8307 | G32: 特快 | H32: 25K | I32: 硬座 | J32: 03车021 | K32: 22.5 | L32: 115 | M32: =K32/L32 -> 0.19565217 | N32: =L32/(Q32*24) -> 78.409091 | O32: 0.44861111 | P32: 0.50972222 | Q32: =P32-O32 -> 0.061111111 | R32: 广州局 | S32: 广州段 | W32: 115km | X32: 阳春-广茂线115km-茂名 | Y32: AC380V | Z32: 双管供风 | AA32: 集便 | AB32: 茂名调向 | AD32: =3000*Q32 -> 183.33333 | AE32: DF4B_2548
A33: 30 | B33: 31 | C33: 45203 | D33: 茂名 | E33: 恩平 | F33: C6926 | G33: 城际 | H33: CRH1A | I33: 二等 | J33: 06车05B | K33: 107 | L33: 180 | M33: =K33/L33 -> 0.59444444 | N33: =L33/(Q33*24) -> 163.63636 | O33: 0.54791667 | P33: 0.59375 | Q33: =P33-O33 -> 0.045833333 | R33: 广州局 | S33: 广州段 | W33: 180km | X33: 茂名-深湛线江湛段180km-恩平 | AD33: =3000*Q33 -> 137.5
B34: 32 | C34: 45203 | D34: 恩平 | E34: 广州南 | F34: C6926 | G34: 城际 | H34: CRH1A | I34: 无座 | J34: - | K34: 98 | L34: 160 | M34: =K34/L34 -> 0.6125 | N34: =L34/(Q34*24) -> 121.51899 | O34: 0.59513889 | P34: 0.65 | Q34: =P34-O34 -> 0.054861111 | R34: 广州局 | S34: 广州段 | W34: 160km | X34: 恩平-深湛线江湛段85km-江门-江门线30km-小榄-广珠城际线45km-广州南 | AD34: =3000*Q34 -> 164.58333
A35: 31 | B35: 33 | C35: 45203 | D35: 广州 | E35: 东莞 | F35: C7003 | G35: 城际 | H35: CRH1A | I35: 二等 | J35: 07车08F | K35: 45.5 | L35: 71 | M35: =K35/L35 -> 0.64084507 | N35: =L35/(Q35*24) -> 78.888889 | O35: 0.70833333 | P35: 0.74583333 | Q35: =P35-O35 -> 0.0375 | R35: 广州局 | S35: 广九段 | W35: 71km | X35: 广州-广九线71km-东莞 | AD35: =3000*Q35 -> 112.5
A36: 32 | B36: 34 | C36: 45299 | D36: 亚布力西 | E36: 哈尔滨 | F36: D7976 | G36: 动车 | H36: CRH5A | I36: 二等 | J36: 06车02F | K36: 68 | L36: 204 | M36: =K36/L36 -> 0.33333333 | N36: =L36/(Q36*24) -> 165.40541 | O36: 0.77430556 | P36: 0.82569444 | Q36: =P36-O36 -> 0.051388889 | R36: 哈尔滨局 | S36: 哈尔滨段 | U36: 正点 | V36: 正点 | W36: 204km | X36: 亚布力西-哈牡客专线204km-哈尔滨 | AD36: =3000*Q36 -> 154.16667
A37: 33 | B37: 35 | C37: 45302 | D37: 哈尔滨 | E37: 齐齐哈尔 | F37: D7981 | G37: 动车 | H37: CRH5A | I37: 二等 | J37: 05车09F | K37: 100 | L37: 285 | M37: =K37/L37 -> 0.35087719 | N37: =L37/(Q37*24) -> 194.31818 | O37: 0.55208333 | P37: 0.61319444 | Q37: =P37-O37 -> 0.061111111 | R37: 哈尔滨局 | S37: 牡丹江段 | U37: 早点1' | V37: 早点1' | W37: 285km | X37: 哈尔滨-哈齐客专线62km-肇东-滨洲线149km-杜尔伯特-哈齐客专线74km-齐齐哈尔 | Y37: 重联 | AD37: =3000*Q37 -> 183.33333
A38: 34 | B38: 36 | C38: 45302 | D38: 齐齐哈尔 | E38: 加格达奇 | F38: K7039 | G38: 快速 | H38: 25G | I38: 硬座 | J38: 01车044 | K38: 64.5 | L38: 431 | M38: =K38/L38 -> 0.14965197 | N38: =L38/(24*"5:43") -> 75.393586 | O38: 0.84791667 | P38: 0.086111111 | Q38: ="24:00"+P38-O38 -> 0.23819444 | R38: 哈尔滨局 | S38: 哈尔滨段 | U38: 晚点9' | V38: 晚点27' | W38: 431km | X38: 齐齐哈尔-齐北线63km-富裕-富西线368km-加格达奇 | Y38: AC380V | Z38: 单管供风 | AA38: 直排 | AB38: 哈尔滨掉向 | AD38: =3000*Q38 -> 714.58333 | AE38: DF4D_0385
B39: 37 | C39: 45303 | D39: 加格达奇 | E39: 漠河 | F39: K7039 | G39: 快速 | H39: 25G | I39: 软卧 | J39: 加1车04上 | K39: 186 | L39: 475 | M39: =K39/L39 -> 0.39157895 | N39: =L39/(Q39*24) -> 61.956522 | O39: 0.10208333 | P39: 0.42152778 | Q39: =P39-O39 -> 0.31944444 | R39: 哈尔滨局 | S39: 哈尔滨段 | U39: 晚点27' | V39: 晚点6' | W39: 475km | X39: 加格达奇-富西线475km-漠河 | Y39: AC380V | Z39: 单管供风 | AA39: 直排 | AB39: 哈尔滨掉向 | AD39: =3000*Q39 -> 958.33333
A40: 35 | B40: 38 | C40: 45306 | D40: 满归 | E40: 根河 | F40: 4182 | G40: 普客 | H40: 25G | I40: 硬座 | J40: 06车001 | K40: 22.5 | L40: 179 | M40: =K40/L40 -> 0.12569832 | N40: =L40/(Q40*24) -> 43.306452 | O40: 0.29722222 | P40: 0.46944444 | Q40: =P40-O40 -> 0.17222222 | R40: 哈尔滨局 | S40: 齐齐哈尔段 | U40: 正点 | V40: 正点 | W40: 179km | X40: 满归-牙林线179km-根河 | Y40: AC380V | Z40: 单管供风 | AA40: 直排 | AD40: =3000*Q40 -> 516.66667 | AE40: DF11
...

Sheet processed
B2: 起点 | D2: 终点 | F2: 总 | K2: 车底 | N2: 里程 | O2: 花费 | P2: 每公里单价 | Q2: 平均速度 | S2: 线路 | U2: 里程 | X2: 车型 | Y2: 次数 | AA2: 里程 | AB2: 花费 | AC2: 每公里单价 | AD2: 平均速度 | AG2: 车次担当局 | AH2: 客运段 | AM2: 里程 | AO2: 花费 | AQ2: 每公里单价 | AS2: 平均速度
B3: 大理 | C3: =COUNTIF(all!D$3:D$1003,B3) -> 1 | D3: 昆明 | E3: =COUNTIF(all!E$3:E$1003,D3) -> 1 | F3: 大理 | G3: =H3+I3 -> 1 | H3: =SUMIF(B:B,F3,C:C) -> 1 | I3: =SUMIF(D:D,F3,E:E) -> 0 | K3: 25B | L3: =COUNTIF(all!H$3:H$1003,K3) -> 0 | M3: =SUMIF(all!H:H,processed!K3,all!Q:Q) -> 0 | N3: =SUMIF(all!H:H,processed!K3,all!L:L) -> 0 | O3: =SUMIF(all!H:H,processed!K3,all!K:K) -> 0 | S3: 京广高铁 | T3: =COUNTIF(detailed_route!F:AJ,processed!S3) -> 3 | U3: =SUMIF(detailed_route_test!A:A,processed!S3,detailed_route_test!B:B) -> 1497 | X3: 动车 | Y3: =COUNTIF(all!G$3:G$1003,X3) -> 23 | Z3: =SUMIF(all!G:G,processed!X3,all!Q:Q) -> 1.0381944 | AA3: =SUMIF(all!G:G,processed!X3,all!L:L) -> 3181 | AB3: =SUMIF(all!G:G,processed!X3,all!K:K) -> 1450 | AC3: =AB3/AA3 -> 0.4558315 | AD3: =AA3/(Z3*24) -> 127.66555 | AE3: D | AG3: 广州局 | AH3: 广州段 | AI3: =COUNTIF(all!S$3:S$1003,AH3) -> 8 | AJ3: =SUM(AI3:AI8) -> 39 | AK3: =SUMIF(all!S:S,processed!AH3,all!Q:Q) -> 0.48819444 | AL3: =SUM(AK3:AK8) -> 1.7402778 | AM3: =SUMIF(all!S:S,processed!AH3,all!L:L) -> 1713 | AN3: =SUM(AM3:AM8) -> 5648 | AO3: =SUMIF(all!S:S,processed!AH3,all!K:K) -> 829 | AP3: =SUM(AO3:AO8) -> 3182.5 | AQ3: =AO3/AM3 -> 0.48394629 | AR3: =AP3/AN3 -> 0.5634738 | AS3: =AM3/(AK3*24) -> 146.20199 | AT3: =AN3/(AL3*24) -> 135.22745
B4: 东莞 | C4: =COUNTIF(all!D$3:D$1003,B4) -> 14 | D4: 厦门 | E4: =COUNTIF(all!E$3:E$1003,D4) -> 1 | F4: 东莞 | G4: =H4+I4 -> 31 | H4: =SUMIF(B:B,F4,C:C) -> 14 | I4: =SUMIF(D:D,F4,E:E) -> 17 | K4: 25G | L4: =COUNTIF(all!H$3:H$1003,K4) -> 9 | M4: =SUMIF(all!H:H,processed!K4,all!Q:Q) -> 1.2930556 | N4: =SUMIF(all!H:H,processed!K4,all!L:L) -> 2134 | O4: =SUMIF(all!H:H,processed!K4,all!K:K) -> 488 | P4: =O4/N4 -> 0.22867854 | Q4: =N4/(M4*24) -> 68.764769 | S4: 广九线 | T4: =COUNTIF(detailed_route!F:AJ,processed!S4) -> 30 | U4: =SUMIF(detailed_route_test!A:A,processed!S4,detailed_route_test!B:B) -> 1360 | X4: 高铁 | Y4: =COUNTIF(all!G$3:G$1003,X4) -> 25 | Z4: =SUMIF(all!G:G,processed!X4,all!Q:Q) -> 1.1722222 | AA4: =SUMIF(all!G:G,processed!X4,all!L:L) -> 4879 | AB4: =SUMIF(all!G:G,processed!X4,all!K:K) -> 2784 | AC4: =AB4/AA4 -> 0.57060873 | AD4: =AA4/(Z4*24) -> 173.42417 | AE4: G | AH4: 长沙段 | AI4: =COUNTIF(all!S$3:S$1003,AH4) -> 4 | AK4: =SUMIF(all!S:S,processed!AH4,all!Q:Q) -> 0.30277778 | AM4: =SUMIF(all!S:S,processed!AH4,all!L:L) -> 1385 | AO4: =SUMIF(all!S:S,processed!AH4,all!K:K) -> 723 | AQ4: =AO4/AM4 -> 0.52202166 | AS4: =AM4/(AK4*24) -> 190.59633
B5: 厦门北 | C5: =COUNTIF(all!D$3:D$1003,B5) -> 1 | D5: 东莞 | E5: =COUNTIF(all!E$3:E$1003,D5) -> 17 | F5: 厦门北 | G5: =H5+I5 -> 1 | H5: =SUMIF(B:B,F5,C:C) -> 1 | I5: =SUMIF(D:D,F5,E:E) -> 0 | K5: 25K | L5: =COUNTIF(all!H$3:H$1003,K5) -> 1 | M5: =SUMIF(all!H:H,processed!K5,all!Q:Q) -> 0.061111111 | N5: =SUMIF(all!H:H,processed!K5,all!L:L) -> 115 | O5: =SUMIF(all!H:H,processed!K5,all!K:K) -> 22.5 | P5: =O5/N5 -> 0.19565217 | Q5: =N5/(M5*24) -> 78.409091 | S5: 广深港高速线 | T5: =COUNTIF(detailed_route!F:AJ,processed!S5) -> 32 | U5: =SUMIF(detailed_route_test!A:A,processed!S5,detailed_route_test!B:B) -> 1303 | X5: 城际 | Y5: =COUNTIF(all!G$3:G$1003,X5) -> 12 | Z5: =SUMIF(all!G:G,processed!X5,all!Q:Q) -> 0.48194444 | AA5: =SUMIF(all!G:G,processed!X5,all!L:L) -> 1405 | AB5: =SUMIF(all!G:G,processed!X5,all!K:K) -> 717.5 | AC5: =AB5/AA5 -> 0.51067616 | AD5: =AA5/(Z5*24) -> 121.46974 | AE5: C | AH5: 广九段 | AI5: =COUNTIF(all!S$3:S$1003,AH5) -> 26 | AK5: =SUMIF(all!S:S,processed!AH5,all!Q:Q) -> 0.9125 | AM5: =SUMIF(all!S:S,processed!AH5,all!L:L) -> 2381 | AO5: =SUMIF(all!S:S,processed!AH5,all!K:K) -> 1559.5 | AQ5: =AO5/AM5 -> 0.6549769 | AS5: =AM5/(AK5*24) -> 108.72146
B6: 东莞南 | C6: =COUNTIF(all!D$3:D$1003,B6) -> 1 | D6: 东莞南 | E6: =COUNTIF(all!E$3:E$1003,D6) -> 1 | F6: 东莞南 | G6: =H6+I6 -> 2 | H6: =SUMIF(B:B,F6,C:C) -> 1 | I6: =SUMIF(D:D,F6,E:E) -> 1 | K6: 25T | L6: =COUNTIF(all!H$3:H$1003,K6) -> 0 | M6: =SUMIF(all!H:H,processed!K6,all!Q:Q) -> 0 | N6: =SUMIF(all!H:H,processed!K6,all!L:L) -> 0 | O6: =SUMIF(all!H:H,processed!K6,all!K:K) -> 0 | S6: 杭深线 | T6: =COUNTIF(detailed_route!F:AJ,processed!S6) -> 3 | U6: =SUMIF(detailed_route_test!A:A,processed!S6,detailed_route_test!B:B) -> 1071 | X6: 快速 | Y6: =COUNTIF(all!G$3:G$1003,X6) -> 7 | Z6: =SUMIF(all!G:G,processed!X6,all!Q:Q) -> 1.0291667 | AA6: =SUMIF(all!G:G,processed!X6,all!L:L) -> 1769 | AB6: =SUMIF(all!G:G,processed!X6,all!K:K) -> 440 | AC6: =AB6/AA6 -> 0.24872809 | AD6: =AA6/(Z6*24) -> 71.619433 | AE6: K | AH6: 怀化段 | AI6: =COUNTIF(all!S$3:S$1003,AH6) -> 0 | AK6: =SUMIF(all!S:S,processed!AH6,all!Q:Q) -> 0 | AM6: =SUMIF(all!S:S,processed!AH6,all!L:L) -> 0 | AO6: =SUMIF(all!S:S,processed!AH6,all!K:K) -> 0
B7: 深圳北 | C7: =COUNTIF(all!D$3:D$1003,B7) -> 18 | D7: 深圳北 | E7: =COUNTIF(all!E$3:E$1003,D7) -> 14 | F7: 深圳北 | G7: =H7+I7 -> 32 | H7: =SUMIF(B:B,F7,C:C) -> 18 | I7: =SUMIF(D:D,F7,E:E) -> 14 | K7: 25Z | L7: =COUNTIF(all!H$3:H$1003,K7) -> 1 | M7: =SUMIF(all!H:H,processed!K7,all!Q:Q) -> 0.079166667 | N7: =SUMIF(all!H:H,processed!K7,all!L:L) -> 117 | O7: =SUMIF(all!H:H,processed!K7,all!K:K) -> 47.5 | P7: =O7/N7 -> 0.40598291 | Q7: =N7/(M7*24) -> 61.578947 | S7: 贵广客专线 | T7: =COUNTIF(detailed_route!F:AJ,processed!S7) -> 2 | U7: =SUMIF(detailed_route_test!A:A,processed!S7,detailed_route_test!B:B) -> 889 | X7: 特快 | Y7: =COUNTIF(all!G$3:G$1003,X7) -> 2 | Z7: =SUMIF(all!G:G,processed!X7,all!Q:Q) -> 0.14027778 | AA7: =SUMIF(all!G:G,processed!X7,all!L:L) -> 232 | AB7: =SUMIF(all!G:G,processed!X7,all!K:K) -> 70 | AC7: =AB7/AA7 -> 0.30172414 | AD7: =AA7/(Z7*24) -> 68.910891 | AE7: T | AH7: 东莞东段 | AI7: =COUNTIF(all!S$3:S$1003,AH7) -> 0 | AK7: =SUMIF(all!S:S,processed!AH7,all!Q:Q) -> 0 | AM7: =SUMIF(all!S:S,processed!AH7,all!L:L) -> 0 | AO7: =SUMIF(all!S:S,processed!AH7,all!K:K) -> 0
B8: 无锡新区 | C8: =COUNTIF(all!D$3:D$1003,B8) -> 1 | D8: 惠东南 | E8: =COUNTIF(all!E$3:E$1003,D8) -> 1 | F8: 无锡新区 | G8: =H8+I8 -> 1 | H8: =SUMIF(B:B,F8,C:C) -> 1 | I8: =SUMIF(D:D,F8,E:E) -> 0 | K8: CR300AF | L8: =COUNTIF(all!H$3:H$1003,K8) -> 8 | M8: =SUMIF(all!H:H,processed!K8,all!Q:Q) -> 0.25972222 | N8: =SUMIF(all!H:H,processed!K8,all!L:L) -> 713 | O8: =SUMIF(all!H:H,processed!K8,all!K:K) -> 588 | P8: =O8/N8 -> 0.82468443 | Q8: =N8/(M8*24) -> 114.38503 | S8: 富西线 | T8: =COUNTIF(detailed_route!F:AJ,processed!S8) -> 2 | U8: =SUMIF(detailed_route_test!A:A,processed!S8,detailed_route_test!B:B) -> 843 | X8: 普客 | Y8: =COUNTIF(all!G$3:G$1003,X8) -> 2 | Z8: =SUMIF(all!G:G,processed!X8,all!Q:Q) -> 0.26388889 | AA8: =SUMIF(all!G:G,processed!X8,all!L:L) -> 365 | AB8: =SUMIF(all!G:G,processed!X8,all!K:K) -> 48 | AC8: =AB8/AA8 -> 0.13150685 | AD8: =AA8/(Z8*24) -> 57.631579 | AE8: - | AH8: 海口段 | AI8: =COUNTIF(all!S$3:S$1003,AH8) -> 1 | AK8: =SUMIF(all!S:S,processed!AH8,all!Q:Q) -> 0.036805556 | AM8: =SUMIF(all!S:S,processed!AH8,all!L:L) -> 169 | AO8: =SUMIF(all!S:S,processed!AH8,all!K:K) -> 71 | AQ8: =AO8/AM8 -> 0.42011834 | AS8: =AM8/(AK8*24) -> 191.32075
B9: 苏州 | C9: =COUNTIF(all!D$3:D$1003,B9) -> 2 | D9: 苏州 | E9: =COUNTIF(all!E$3:E$1003,D9) -> 1 | F9: 苏州 | G9: =H9+I9 -> 3 | H9: =SUMIF(B:B,F9,C:C) -> 2 | I9: =SUMIF(D:D,F9,E:E) -> 1 | K9: CR400AF | L9: =COUNTIF(all!H$3:H$1003,K9) -> 3 | M9: =SUMIF(all!H:H,processed!K9,all!Q:Q) -> 0.26319444 | N9: =SUMIF(all!H:H,processed!K9,all!L:L) -> 1322 | O9: =SUMIF(all!H:H,processed!K9,all!K:K) -> 634 | P9: =O9/N9 -> 0.4795764 | Q9: =N9/(M9*24) -> 209.2876 | S9: 广茂线 | T9: =COUNTIF(detailed_route!F:AJ,processed!S9) -> 4 | U9: =SUMIF(detailed_route_test!A:A,processed!S9,detailed_route_test!B:B) -> 607 | X9: 直达 | Y9: =COUNTIF(all!G$3:G$1003,X9) -> 0 | Z9: =SUMIF(all!G:G,processed!X9,all!Q:Q) -> 0 | AA9: =SUMIF(all!G:G,processed!X9,all!L:L) -> 0 | AB9: =SUMIF(all!G:G,processed!X9,all!K:K) -> 0 | AE9: Z | AG9: 上海局 | AH9: 上海段 | AI9: =COUNTIF(all!S$3:S$1003,AH9) -> 0 | AJ9: =AI9+AI10+AI11+AI12 -> 5 | AK9: =SUMIF(all!S:S,processed!AH9,all!Q:Q) -> 0 | AL9: =SUM(AK9:AK12) -> 0.10486111 | AM9: =SUMIF(all!S:S,processed!AH9,all!L:L) -> 0 | AN9: =SUM(AM9:AM12) -> 344 | AO9: =SUMIF(all!S:S,processed!AH9,all!K:K) -> 0 | AP9: =SUM(AO9:AO12) -> 185 | AR9: =AP9/AN9 -> 0.5377907 | AT9: =AN9/(AL9*24) -> 136.68874
B10: 无锡 | C10: =COUNTIF(all!D$3:D$1003,B10) -> 1 | D10: 阳澄湖 | E10: =COUNTIF(all!E$3:E$1003,D10) -> 1 | F10: 无锡 | G10: =H10+I10 -> 2 | H10: =SUMIF(B:B,F10,C:C) -> 1 | I10: =SUMIF(D:D,F10,E:E) -> 1 | K10: CR400AF-A | L10: =COUNTIF(all!H$3:H$1003,K10) -> 1 | M10: =SUMIF(all!H:H,processed!K10,all!Q:Q) -> 0.011805556 | N10: =SUMIF(all!H:H,processed!K10,all!L:L) -> 52 | O10: =SUMIF(all!H:H,processed!K10,all!K:K) -> 39.5 | P10: =O10/N10 -> 0.75961538 | Q10: =N10/(M10*24) -> 183.52941 | S10: 深湛线江湛段 | T10: =COUNTIF(detailed_route!F:AJ,processed!S10) -> 3 | U10: =SUMIF(detailed_route_test!A:A,processed!S10,detailed_route_test!B:B) -> 413 | X10: 旅游 | Y10: =COUNTIF(all!G$3:G$1003,X10) -> 0 | Z10: =SUMIF(all!G:G,processed!X10,all!Q:Q) -> 0 | AA10: =SUMIF(all!G:G,processed!X10,all!L:L) -> 0 | AB10: =SUMIF(all!G:G,processed!X10,all!K:K) -> 0 | AE10: Y | AH10: 南京段 | AI10: =COUNTIF(all!S$3:S$1003,AH10) -> 4 | AK10: =SUMIF(all!S:S,processed!AH10,all!Q:Q) -> 0.077777778 | AM10: =SUMIF(all!S:S,processed!AH10,all!L:L) -> 270 | AO10: =SUMIF(all!S:S,processed!AH10,all!K:K) -> 131 | AQ10: =AO10/AM10 -> 0.48518519 | AS10: =AM10/(AK10*24) -> 144.64286
B11: 长沙南 | C11: =COUNTIF(all!D$3:D$1003,B11) -> 1 | D11: 无锡 | E11: =COUNTIF(all!E$3:E$1003,D11) -> 1 | F11: 长沙南 | G11: =H11+I11 -> 2 | H11: =SUMIF(B:B,F11,C:C) -> 1 | I11: =SUMIF(D:D,F11,E:E) -> 1 | K11: CR400BF | L11: =COUNTIF(all!H$3:H$1003,K11) -> 1 | M11: =SUMIF(all!H:H,processed!K11,all!Q:Q) -> 0.01875 | N11: =SUMIF(all!H:H,processed!K11,all!L:L) -> 56 | O11: =SUMIF(all!H:H,processed!K11,all!K:K) -> 75 | P11: =O11/N11 -> 1.3392857 | Q11: =N11/(M11*24) -> 124.44444 | S11: 京港高铁赣深段 | T11: =COUNTIF(detailed_route!F:AJ,processed!S11) -> 20 | U11: =SUMIF(detailed_route_test!A:A,processed!S11,detailed_route_test!B:B) -> 380 | X11: 临客 | Y11: =COUNTIF(all!G$3:G$1003,X11) -> 0 | Z11: =SUMIF(all!G:G,processed!X11,all!Q:Q) -> 0 | AA11: =SUMIF(all!G:G,processed!X11,all!L:L) -> 0 | AB11: =SUMIF(all!G:G,processed!X11,all!K:K) -> 0 | AE11: L | AH11: 杭州段 | AI11: =COUNTIF(all!S$3:S$1003,AH11) -> 1 | AK11: =SUMIF(all!S:S,processed!AH11,all!Q:Q) -> 0.027083333 | AM11: =SUMIF(all!S:S,processed!AH11,all!L:L) -> 74 | AO11: =SUMIF(all!S:S,processed!AH11,all!K:K) -> 54 | AQ11: =AO11/AM11 -> 0.72972973 | AS11: =AM11/(AK11*24) -> 113.84615
B12: 广州 | C12: =COUNTIF(all!D$3:D$1003,B12) -> 3 | D12: 南京 | E12: =COUNTIF(all!E$3:E$1003,D12) -> 1 | F12: 广州 | G12: =H12+I12 -> 4 | H12: =SUMIF(B:B,F12,C:C) -> 3 | I12: =SUMIF(D:D,F12,E:E) -> 1 | K12: CR400BF-Z | L12: =COUNTIF(all!H$3:H$1003,K12) -> 1 | M12: =SUMIF(all!H:H,processed!K12,all!Q:Q) -> 0.0125 | N12: =SUMIF(all!H:H,processed!K12,all!L:L) -> 50 | O12: =SUMIF(all!H:H,processed!K12,all!K:K) -> 34.5 | P12: =O12/N12 -> 0.69 | Q12: =N12/(M12*24) -> 166.66667 | S12: 滨洲线 | T12: =COUNTIF(detailed_route!F:AJ,processed!S12) -> 2 | U12: =SUMIF(detailed_route_test!A:A,processed!S12,detailed_route_test!B:B) -> 335 | X12: 市郊 | Y12: 0 | Z12: =SUMIF(all!G:G,processed!X12,all!Q:Q) -> 0 | AA12: =SUMIF(all!G:G,processed!X12,all!L:L) -> 0 | AB12: =SUMIF(all!G:G,processed!X12,all!K:K) -> 0 | AE12: S | AH12: 合肥段 | AI12: =COUNTIF(all!S$3:S$1003,AH12) -> 0 | AK12: =SUMIF(all!S:S,processed!AH12,all!Q:Q) -> 0 | AM12: =SUMIF(all!S:S,processed!AH12,all!L:L) -> 0 | AO12: =SUMIF(all!S:S,processed!AH12,all!K:K) -> 0
B13: 阳江 | C13: =COUNTIF(all!D$3:D$1003,B13) -> 1 | D13: 长沙南 | E13: =COUNTIF(all!E$3:E$1003,D13) -> 1 | F13: 阳江 | G13: =H13+I13 -> 1 | H13: =SUMIF(B:B,F13,C:C) -> 1 | I13: =SUMIF(D:D,F13,E:E) -> 0 | K13: CRH1A | L13: =COUNTIF(all!H$3:H$1003,K13) -> 7 | M13: =SUMIF(all!H:H,processed!K13,all!Q:Q) -> 0.27291667 | N13: =SUMIF(all!H:H,processed!K13,all!L:L) -> 706 | O13: =SUMIF(all!H:H,processed!K13,all!K:K) -> 456.5 | P13: =O13/N13 -> 0.64660057 | Q13: =N13/(M13*24) -> 107.78626 | S13: 长珲城际线 | T13: =COUNTIF(detailed_route!F:AJ,processed!S13) -> 2 | U13: =SUMIF(detailed_route_test!A:A,processed!S13,detailed_route_test!B:B) -> 299 | X13: 管内 | Y13: 0 | Z13: =SUMIF(all!G:G,processed!X13,all!Q:Q) -> 0 | AA13: =SUMIF(all!G:G,processed!X13,all!L:L) -> 0 | AB13: =SUMIF(all!G:G,processed!X13,all!K:K) -> 0 | AE13: N | AG13: 哈尔滨局 | AH13: 哈尔滨段 | AI13: =COUNTIF(all!S$3:S$1003,AH13) -> 3 | AJ13: =AI13+AI14+AI15 -> 6 | AK13: =SUMIF(all!S:S,processed!AH13,all!Q:Q) -> 0.60902778 | AL13: =SUM(AK13:AK15) -> 0.93402778 | AM13: =SUMIF(all!S:S,processed!AH13,all!L:L) -> 1110 | AN13: =SUM(AM13:AM15) -> 1760 | AO13: =SUMIF(all!S:S,processed!AH13,all!K:K) -> 318.5 | AP13: =SUM(AO13:AO15) -> 466.5 | AQ13: =AO13/AM13 -> 0.28693694 | AR13: =AP13/AN13 -> 0.26505682 | AS13: =AM13/(AK13*24) -> 75.940707 | AT13: =AN13/(AL13*24) -> 78.513011
B14: 江门 | C14: =COUNTIF(all!D$3:D$1003,B14) -> 1 | D14: 广州 | E14: =COUNTIF(all!E$3:E$1003,D14) -> 1 | F14: 江门 | G14: =H14+I14 -> 2 | H14: =SUMIF(B:B,F14,C:C) -> 1 | I14: =SUMIF(D:D,F14,E:E) -> 1 | K14: CRH1A-A | L14: =COUNTIF(all!H$3:H$1003,K14) -> 13 | M14: =SUMIF(all!H:H,processed!K14,all!Q:Q) -> 0.62847222 | N14: =SUMIF(all!H:H,processed!K14,all!L:L) -> 1895 | O14: =SUMIF(all!H:H,processed!K14,all!K:K) -> 805 | P14: =O14/N14 -> 0.42480211 | Q14: =N14/(M14*24) -> 125.63536 | S14: 沪昆高速线 | T14: =COUNTIF(detailed_route!F:AJ,processed!S14) -> 1 | U14: =SUMIF(detailed_route_test!A:A,processed!S14,detailed_route_test!B:B) -> 251 | AH14: 牡丹江段 | AI14: =COUNTIF(all!S$3:S$1003,AH14) -> 1 | AK14: =SUMIF(all!S:S,processed!AH14,all!Q:Q) -> 0.061111111 | AM14: =SUMIF(all!S:S,processed!AH14,all!L:L) -> 285 | AO14: =SUMIF(all!S:S,processed!AH14,all!K:K) -> 100 | AQ14: =AO14/AM14 -> 0.35087719 | AS14: =AM14/(AK14*24) -> 194.31818
B15: 阳春 | C15: =COUNTIF(all!D$3:D$1003,B15) -> 1 | D15: 阳春 | E15: =COUNTIF(all!E$3:E$1003,D15) -> 2 | F15: 阳春 | G15: =H15+I15 -> 3 | H15: =SUMIF(B:B,F15,C:C) -> 1 | I15: =SUMIF(D:D,F15,E:E) -> 2 | K15: CRH1B | L15: =COUNTIF(all!H$3:H$1003,K15) -> 1 | M15: =SUMIF(all!H:H,processed!K15,all!Q:Q) -> 0.0076388889 | N15: =SUMIF(all!H:H,processed!K15,all!L:L) -> 25 | O15: =SUMIF(all!H:H,processed!K15,all!K:K) -> 9 | P15: =O15/N15 -> 0.36 | Q15: =N15/(M15*24) -> 136.36364 | S15: 广珠城际线 | T15: =COUNTIF(detailed_route!F:AJ,processed!S15) -> 4 | U15: =SUMIF(detailed_route_test!A:A,processed!S15,detailed_route_test!B:B) -> 210 | AH15: 齐齐哈尔段 | AI15: =COUNTIF(all!S$3:S$1003,AH15) -> 2 | AK15: =SUMIF(all!S:S,processed!AH15,all!Q:Q) -> 0.26388889 | AM15: =SUMIF(all!S:S,processed!AH15,all!L:L) -> 365 | AO15: =SUMIF(all!S:S,processed!AH15,all!K:K) -> 48 | AQ15: =AO15/AM15 -> 0.13150685 | AS15: =AM15/(AK15*24) -> 57.631579
B16: 茂名 | C16: =COUNTIF(all!D$3:D$1003,B16) -> 1 | D16: 江门 | E16: =COUNTIF(all!E$3:E$1003,D16) -> 1 | F16: 茂名 | G16: =H16+I16 -> 2 | H16: =SUMIF(B:B,F16,C:C) -> 1 | I16: =SUMIF(D:D,F16,E:E) -> 1 | K16: CRH1E | L16: =COUNTIF(all!H$3:H$1003,K16) -> 1 | M16: =SUMIF(all!H:H,processed!K16,all!Q:Q) -> 0.027083333 | N16: =SUMIF(all!H:H,processed!K16,all!L:L) -> 74 | O16: =SUMIF(all!H:H,processed!K16,all!K:K) -> 54 | P16: =O16/N16 -> 0.72972973 | Q16: =N16/(M16*24) -> 113.84615 | S16: 哈牡客专线 | T16: =COUNTIF(detailed_route!F:AJ,processed!S16) -> 1 | U16: =SUMIF(detailed_route_test!A:A,processed!S16,detailed_route_test!B:B) -> 204 | X16: 坐席 | AA16: 里程 | AB16: 花费 | AC16: 每公里单价 | AD16: 平均速度 | AG16: 成都局 | AH16: 成都段 | AI16: =COUNTIF(all!S$3:S$1003,AH16) -> 0 | AJ16: =AI16+AI17+AI18 -> 3 | AK16: =SUMIF(all!S:S,processed!AH16,all!Q:Q) -> 0 | AL16: =SUM(AK16:AK18) -> 0.23680556 | AM16: =SUMIF(all!S:S,processed!AH16,all!L:L) -> 0 | AN16: =SUM(AM16:AM18) -> 576 | AO16: =SUMIF(all!S:S,processed!AH16,all!K:K) -> 0 | AP16: =SUM(AO16:AO18) -> 238.5 | AR16: =AP16/AN16 -> 0.4140625 | AT16: =AN16/(AL16*24) -> 101.34897
B17: 恩平 | C17: =COUNTIF(all!D$3:D$1003,B17) -> 1 | D17: 虎门 | E17: =COUNTIF(all!E$3:E$1003,D17) -> 2 | F17: 恩平 | G17: =H17+I17 -> 2 | H17: =SUMIF(B:B,F17,C:C) -> 1 | I17: =SUMIF(D:D,F17,E:E) -> 1 | K17: CRH2A | L17: =COUNTIF(all!H$3:H$1003,K17) -> 5 | M17: =SUMIF(all!H:H,processed!K17,all!Q:Q) -> 0.22638889 | N17: =SUMIF(all!H:H,processed!K17,all!L:L) -> 624 | O17: =SUMIF(all!H:H,processed!K17,all!K:K) -> 357 | P17: =O17/N17 -> 0.57211538 | Q17: =N17/(M17*24) -> 114.84663 | S17: 京广线 | T17: =COUNTIF(detailed_route!F:AJ,processed!S17) -> 1 | U17: =SUMIF(detailed_route_test!A:A,processed!S17,detailed_route_test!B:B) -> 194 | X17: 特等 | Y17: =COUNTIF(all!I$3:I$1003,X17) -> 0 | Z17: =SUMIF(all!I:I,processed!X17,all!Q:Q) -> 0 | AA17: =SUMIF(all!I:I,processed!X17,all!L:L) -> 0 | AB17: =SUMIF(all!I:I,processed!X17,all!K:K) -> 0 | AH17: 重庆段 | AI17: =COUNTIF(all!S$3:S$1003,AH17) -> 2 | AK17: =SUMIF(all!S:S,processed!AH17,all!Q:Q) -> 0.175 | AM17: =SUMIF(all!S:S,processed!AH17,all!L:L) -> 361 | AO17: =SUMIF(all!S:S,processed!AH17,all!K:K) -> 145.5 | AQ17: =AO17/AM17 -> 0.40304709 | AS17: =AM17/(AK17*24) -> 85.952381
B18: 亚布力西 | C18: =COUNTIF(all!D$3:D$1003,B18) -> 1 | D18: 茂名 | E18: =COUNTIF(all!E$3:E$1003,D18) -> 1 | F18: 亚布力西 | G18: =H18+I18 -> 1 | H18: =SUMIF(B:B,F18,C:C) -> 1 | I18: =SUMIF(D:D,F18,E:E) -> 0 | K18: CRH2C | L18: =COUNTIF(all!H$3:H$1003,K18) -> 2 | M18: =SUMIF(all!H:H,processed!K18,all!Q:Q) -> 0.052083333 | N18: =SUMIF(all!H:H,processed!K18,all!L:L) -> 203 | O18: =SUMIF(all!H:H,processed!K18,all!K:K) -> 101 | P18: =O18/N18 -> 0.49753695 | Q18: =N18/(M18*24) -> 162.4 | S18: 牙林线 | T18: =COUNTIF(detailed_route!F:AJ,processed!S18) -> 1 | U18: =SUMIF(detailed_route_test!A:A,processed!S18,detailed_route_test!B:B) -> 179 | X18: 一等 | Y18: =COUNTIF(all!I$3:I$1003,X18) -> 1 | Z18: =SUMIF(all!I:I,processed!X18,all!Q:Q) -> 0.0097222222 | AA18: =SUMIF(all!I:I,processed!X18,all!L:L) -> 32 | AB18: =SUMIF(all!I:I,processed!X18,all!K:K) -> 13 | AC18: =AB18/AA18 -> 0.40625 | AD18: =AA18/(Z18*24) -> 137.14286 | AH18: 贵阳段 | AI18: =COUNTIF(all!S$3:S$1003,AH18) -> 1 | AK18: =SUMIF(all!S:S,processed!AH18,all!Q:Q) -> 0.061805556 | AM18: =SUMIF(all!S:S,processed!AH18,all!L:L) -> 215 | AO18: =SUMIF(all!S:S,processed!AH18,all!K:K) -> 93 | AQ18: =AO18/AM18 -> 0.43255814 | AS18: =AM18/(AK18*24) -> 144.94382
B19: 哈尔滨 | C19: =COUNTIF(all!D$3:D$1003,B19) -> 1 | D19: 恩平 | E19: =COUNTIF(all!E$3:E$1003,D19) -> 1 | F19: 哈尔滨 | G19: =H19+I19 -> 2 | H19: =SUMIF(B:B,F19,C:C) -> 1 | I19: =SUMIF(D:D,F19,E:E) -> 1 | K19: CRH2C-2 | L19: =COUNTIF(all!H$3:H$1003,K19) -> 1 | M19: =SUMIF(all!H:H,processed!K19,all!Q:Q) -> 0.018055556 | N19: =SUMIF(all!H:H,processed!K19,all!L:L) -> 42 | O19: =SUMIF(all!H:H,processed!K19,all!K:K) -> 21 | P19: =O19/N19 -> 0.5 | Q19: =N19/(M19*24) -> 96.923077 | S19: 楚大线 | T19: =COUNTIF(detailed_route!F:AJ,processed!S19) -> 1 | U19: =SUMIF(detailed_route_test!A:A,processed!S19,detailed_route_test!B:B) -> 175 | X19: 二等 | Y19: =COUNTIF(all!I$3:I$1003,X19) -> 57 | Z19: =SUMIF(all!I:I,processed!X19,all!Q:Q) -> 2.5625 | AA19: =SUMIF(all!I:I,processed!X19,all!L:L) -> 9096 | AB19: =SUMIF(all!I:I,processed!X19,all!K:K) -> 4709 | AC19: =AB19/AA19 -> 0.51770009 | AD19: =AA19/(Z19*24) -> 147.90244 | AG19: 南昌局 | AH19: 南昌段 | AI19: =COUNTIF(all!S$3:S$1003,AH19) -> 3 | AJ19: =AI19+AI20 -> 5 | AK19: =SUMIF(all!S:S,processed!AH19,all!Q:Q) -> 0.10208333 | AL19: =AK19+AK20 -> 0.28680556 | AM19: =SUMIF(all!S:S,processed!AH19,all!L:L) -> 222 | AN19: =SUM(AM19:AM20) -> 872 | AO19: =SUMIF(all!S:S,processed!AH19,all!K:K) -> 158 | AP19: =SUM(AO19:AO20) -> 335 | AQ19: =AO19/AM19 -> 0.71171171 | AR19: =AP19/AN19 -> 0.38417431 | AS19: =AM19/(AK19*24) -> 90.612245 | AT19: =AN19/(AL19*24) -> 126.68281
B20: 齐齐哈尔 | C20: =COUNTIF(all!D$3:D$1003,B20) -> 1 | D20: 广州南 | E20: =COUNTIF(all!E$3:E$1003,D20) -> 4 | F20: 齐齐哈尔 | G20: =H20+I20 -> 2 | H20: =SUMIF(B:B,F20,C:C) -> 1 | I20: =SUMIF(D:D,F20,E:E) -> 1 | K20: CRH380AL | L20: =COUNTIF(all!H$3:H$1003,K20) -> 3 | M20: =SUMIF(all!H:H,processed!K20,all!Q:Q) -> 0.080555556 | N20: =SUMIF(all!H:H,processed!K20,all!L:L) -> 337 | O20: =SUMIF(all!H:H,processed!K20,all!K:K) -> 218.5 | P20: =O20/N20 -> 0.64836795 | Q20: =N20/(M20*24) -> 174.31034 | S20: 贵南线 | T20: =COUNTIF(detailed_route!F:AJ,processed!S20) -> 1 | U20: =SUMIF(detailed_route_test!A:A,processed!S20,detailed_route_test!B:B) -> 175 | X20: 商务 | Y20: =COUNTIF(all!I$3:I$1003,X20) -> 0 | Z20: =SUMIF(all!I:I,processed!X20,all!Q:Q) -> 0 | AA20: =SUMIF(all!I:I,processed!X20,all!L:L) -> 0 | AB20: =SUMIF(all!I:I,processed!X20,all!K:K) -> 0 | AH20: 福州段 | AI20: =COUNTIF(all!S$3:S$1003,AH20) -> 2 | AK20: =SUMIF(all!S:S,processed!AH20,all!Q:Q) -> 0.18472222 | AM20: =SUMIF(all!S:S,processed!AH20,all!L:L) -> 650 | AO20: =SUMIF(all!S:S,processed!AH20,all!K:K) -> 177 | AQ20: =AO20/AM20 -> 0.27230769 | AS20: =AM20/(AK20*24) -> 146.61654
B21: 加格达奇 | C21: =COUNTIF(all!D$3:D$1003,B21) -> 1 | D21: 哈尔滨 | E21: =COUNTIF(all!E$3:E$1003,D21) -> 1 | F21: 加格达奇 | G21: =H21+I21 -> 2 | H21: =SUMIF(B:B,F21,C:C) -> 1 | I21: =SUMIF(D:D,F21,E:E) -> 1 | K21: CRH380B | L21: =COUNTIF(all!H$3:H$1003,K21) -> 3 | M21: =SUMIF(all!H:H,processed!K21,all!Q:Q) -> 0.24583333 | N21: =SUMIF(all!H:H,processed!K21,all!L:L) -> 1134 | O21: =SUMIF(all!H:H,processed!K21,all!K:K) -> 608 | P21: =O21/N21 -> 0.5361552 | Q21: =N21/(M21*24) -> 192.20339 | S21: 海南环岛高铁线东段 | T21: =COUNTIF(detailed_route!F:AJ,processed!S21) -> 1 | U21: =SUMIF(detailed_route_test!A:A,processed!S21,detailed_route_test!B:B) -> 169 | X21: 硬座 | Y21: =COUNTIF(all!I$3:I$1003,X21) -> 8 | Z21: =SUMIF(all!I:I,processed!X21,all!Q:Q) -> 0.89097222 | AA21: =SUMIF(all!I:I,processed!X21,all!L:L) -> 1528 | AB21: =SUMIF(all!I:I,processed!X21,all!K:K) -> 233 | AC21: =AB21/AA21 -> 0.15248691 | AD21: =AA21/(Z21*24) -> 71.457521 | AG21: 西安局 | AH21: 西安段 | AI21: =COUNTIF(all!S$3:S$1003,AH21) -> 3 | AJ21: =AI21 -> 3 | AK21: =SUMIF(all!S:S,processed!AH21,all!Q:Q) -> 0.21388889 | AL21: =AK21 -> 0.21388889 | AM21: =SUMIF(all!S:S,processed!AH21,all!L:L) -> 1044 | AN21: =AM21 -> 1044 | AO21: =SUMIF(all!S:S,processed!AH21,all!K:K) -> 532.5 | AP21: =AO21 -> 532.5 | AQ21: =AO21/AM21 -> 0.51005747 | AR21: =AP21/AN21 -> 0.51005747 | AS21: =AM21/(AK21*24) -> 203.37662 | AT21: =AN21/(AL21*24) -> 203.37662
B22: 满归 | C22: =COUNTIF(all!D$3:D$1003,B22) -> 1 | D22: 齐齐哈尔 | E22: =COUNTIF(all!E$3:E$1003,D22) -> 1 | F22: 满归 | G22: =H22+I22 -> 1 | H22: =SUMIF(B:B,F22,C:C) -> 1 | I22: =SUMIF(D:D,F22,E:E) -> 0 | K22: CRH380BL | L22: =COUNTIF(all!H$3:H$1003,K22) -> 1 | M22: =SUMIF(all!H:H,processed!K22,all!Q:Q) -> 0.15347222 | N22: =SUMIF(all!H:H,processed!K22,all!L:L) -> 809 | O22: =SUMIF(all!H:H,processed!K22,all!K:K) -> 388.5 | P22: =O22/N22 -> 0.4802225 | Q22: =N22/(M22*24) -> 219.63801 | S22: 京沪线 | T22: =COUNTIF(detailed_route!F:AJ,processed!S22) -> 2 | U22: =SUMIF(detailed_route_test!A:A,processed!S22,detailed_route_test!B:B) -> 147 | X22: 软座 | Y22: =COUNTIF(all!I$3:I$1003,X22) -> 1 | Z22: =SUMIF(all!I:I,processed!X22,all!Q:Q) -> 0.079166667 | AA22: =SUMIF(all!I:I,processed!X22,all!L:L) -> 117 | AB22: =SUMIF(all!I:I,processed!X22,all!K:K) -> 47.5 | AC22: =AB22/AA22 -> 0.40598291 | AD22: =AA22/(Z22*24) -> 61.578947 | AG22: 南宁局 | AH22: 南宁段 | AI22: =COUNTIF(all!S$3:S$1003,AH22) -> 2 | AJ22: =AI22 -> 2 | AK22: =SUMIF(all!S:S,processed!AH22,all!Q:Q) -> 0.10625 | AL22: =AK22 -> 0.10625 | AM22: =SUMIF(all!S:S,processed!AH22,all!L:L) -> 211 | AN22: =AM22 -> 211 | AO22: =SUMIF(all!S:S,processed!AH22,all!K:K) -> 75.5 | AP22: =AO22 -> 75.5 | AQ22: =AO22/AM22 -> 0.35781991 | AR22: =AP22/AN22 -> 0.35781991 | AS22: =AM22/(AK22*24) -> 82.745098 | AT22: =AN22/(AL22*24) -> 82.745098
B23: 海拉尔 | C23: =COUNTIF(all!D$3:D$1003,B23) -> 1 | D23: 加格达奇 | E23: =COUNTIF(all!E$3:E$1003,D23) -> 1 | F23: 海拉尔 | G23: =H23+I23 -> 1 | H23: =SUMIF(B:B,F23,C:C) -> 1 | I23: =SUMIF(D:D,F23,E:E) -> 0 | K23: CRH380D | L23: =COUNTIF(all!H$3:H$1003,K23) -> 1 | M23: =SUMIF(all!H:H,processed!K23,all!Q:Q) -> 0.061805556 | N23: =SUMIF(all!H:H,processed!K23,all!L:L) -> 215 | O23: =SUMIF(all!H:H,processed!K23,all!K:K) -> 93 | P23: =O23/N23 -> 0.43255814 | Q23: =N23/(M23*24) -> 144.94382 | S23: 哈齐客专线 | T23: =COUNTIF(detailed_route!F:AJ,processed!S23) -> 2 | U23: =SUMIF(detailed_route_test!A:A,processed!S23,detailed_route_test!B:B) -> 136 | X23: 硬卧 | Y23: =COUNTIF(all!I$3:I$1003,X23) -> 1 | Z23: =SUMIF(all!I:I,processed!X23,all!Q:Q) -> 0.14375 | AA23: =SUMIF(all!I:I,processed!X23,all!L:L) -> 246 | AB23: =SUMIF(all!I:I,processed!X23,all!K:K) -> 91.5 | AC23: =AB23/AA23 -> 0.37195122 | AD23: =AA23/(Z23*24) -> 71.304348 | AG23: 昆明局 | AH23: 昆明段 | AI23: =COUNTIF(all!S$3:S$1003,AH23) -> 1 | AJ23: =AI23 -> 1 | AK23: =SUMIF(all!S:S,processed!AH23,all!Q:Q) -> 0.097222222 | AL23: =AK23 -> 0.097222222 | AM23: =SUMIF(all!S:S,processed!AH23,all!L:L) -> 328 | AN23: =AM23 -> 328 | AO23: =SUMIF(all!S:S,processed!AH23,all!K:K) -> 145 | AP23: =AO23 -> 145 | AQ23: =AO23/AM23 -> 0.44207317 | AR23: =AP23/AN23 -> 0.44207317 | AS23: =AM23/(AK23*24) -> 140.57143 | AT23: =AN23/(AL23*24) -> 140.57143
B24: 翠亨 | C24: =COUNTIF(all!D$3:D$1003,B24) -> 1 | D24: 漠河 | E24: =COUNTIF(all!E$3:E$1003,D24) -> 1 | F24: 翠亨 | G24: =H24+I24 -> 1 | H24: =SUMIF(B:B,F24,C:C) -> 1 | I24: =SUMIF(D:D,F24,E:E) -> 0 | K24: CRH3C | L24: =COUNTIF(all!H$3:H$1003,K24) -> 1 | M24: =SUMIF(all!H:H,processed!K24,all!Q:Q) -> 0.03125 | N24: =SUMIF(all!H:H,processed!K24,all!L:L) -> 115 | O24: =SUMIF(all!H:H,processed!K24,all!K:K) -> 54 | P24: =O24/N24 -> 0.46956522 | Q24: =N24/(M24*24) -> 153.33333 | S24: 广昆线广温段 | T24: =COUNTIF(detailed_route!F:AJ,processed!S24) -> 1 | U24: =SUMIF(detailed_route_test!A:A,processed!S24,detailed_route_test!B:B) -> 121 | X24: 软卧 | Y24: =COUNTIF(all!I$3:I$1003,X24) -> 1 | Z24: =SUMIF(all!I:I,processed!X24,all!Q:Q) -> 0.31944444 | AA24: =SUMIF(all!I:I,processed!X24,all!L:L) -> 475 | AB24: =SUMIF(all!I:I,processed!X24,all!K:K) -> 186 | AC24: =AB24/AA24 -> 0.39157895 | AD24: =AA24/(Z24*24) -> 61.956522 | AG24: 武汉局 | AH24: 襄阳段 | AI24: =COUNTIF(all!S$3:S$1003,AH24) -> 2 | AJ24: =AI24 -> 2 | AK24: =SUMIF(all!S:S,processed!AH24,all!Q:Q) -> 0.084722222 | AL24: =AK24 -> 0.084722222 | AM24: =SUMIF(all!S:S,processed!AH24,all!L:L) -> 136 | AN24: =AM24 -> 136 | AO24: =SUMIF(all!S:S,processed!AH24,all!K:K) -> 25 | AP24: =AO24 -> 25 | AQ24: =AO24/AM24 -> 0.18382353 | AR24: =AP24/AN24 -> 0.18382353 | AS24: =AM24/(AK24*24) -> 66.885246 | AT24: =AN24/(AL24*24) -> 66.885246
B25: 广州南 | C25: =COUNTIF(all!D$3:D$1003,B25) -> 3 | D25: 根河 | E25: =COUNTIF(all!E$3:E$1003,D25) -> 1 | F25: 广州南 | G25: =H25+I25 -> 7 | H25: =SUMIF(B:B,F25,C:C) -> 3 | I25: =SUMIF(D:D,F25,E:E) -> 4 | K25: CRH5A | L25: =COUNTIF(all!H$3:H$1003,K25) -> 2 | M25: =SUMIF(all!H:H,processed!K25,all!Q:Q) -> 0.1125 | N25: =SUMIF(all!H:H,processed!K25,all!L:L) -> 489 | O25: =SUMIF(all!H:H,processed!K25,all!K:K) -> 168 | P25: =O25/N25 -> 0.34355828 | Q25: =N25/(M25*24) -> 181.11111 | S25: 沈佳高铁白敦段 | T25: =COUNTIF(detailed_route!F:AJ,processed!S25) -> 1 | U25: =SUMIF(detailed_route_test!A:A,processed!S25,detailed_route_test!B:B) -> 99 | X25: 高软 | Y25: =COUNTIF(all!I$3:I$1003,X25) -> 0 | Z25: =SUMIF(all!I:I,processed!X25,all!Q:Q) -> 0 | AA25: =SUMIF(all!I:I,processed!X25,all!L:L) -> 0 | AB25: =SUMIF(all!I:I,processed!X25,all!K:K) -> 0 | AG25: 太原局 | AH25: 太原段 | AI25: =COUNTIF(all!S$3:S$1003,AH25) -> 1 | AJ25: =AI25 -> 1 | AK25: =SUMIF(all!S:S,processed!AH25,all!Q:Q) -> 0.16388889 | AL25: =AK25 -> 0.16388889 | AM25: =SUMIF(all!S:S,processed!AH25,all!L:L) -> 344 | AN25: =AM25 -> 344 | AO25: =SUMIF(all!S:S,processed!AH25,all!K:K) -> 51.5 | AP25: =AO25 -> 51.5 | AQ25: =AO25/AM25 -> 0.1497093 | AR25: =AP25/AN25 -> 0.1497093 | AS25: =AM25/(AK25*24) -> 87.457627 | AT25: =AN25/(AL25*24) -> 87.457627
B26: 肇庆 | C26: =COUNTIF(all!D$3:D$1003,B26) -> 1 | D26: 满洲里 | E26: =COUNTIF(all!E$3:E$1003,D26) -> 1 | F26: 肇庆 | G26: =H26+I26 -> 2 | H26: =SUMIF(B:B,F26,C:C) -> 1 | I26: =SUMIF(D:D,F26,E:E) -> 1 | K26: CRH5G | L26: =COUNTIF(all!H$3:H$1003,K26) -> 2 | M26: =SUMIF(all!H:H,processed!K26,all!Q:Q) -> 0.11805556 | N26: =SUMIF(all!H:H,processed!K26,all!L:L) -> 410 | O26: =SUMIF(all!H:H,processed!K26,all!K:K) -> 123 | P26: =O26/N26 -> 0.3 | Q26: =N26/(M26*24) -> 144.70588 | S26: 沪宁高速线 | T26: =COUNTIF(detailed_route!F:AJ,processed!S26) -> 3 | U26: =SUMIF(detailed_route_test!A:A,processed!S26,detailed_route_test!B:B) -> 81 | X26: 一等卧 | Y26: =COUNTIF(all!I$3:I$1003,X26) -> 0 | Z26: =SUMIF(all!I:I,processed!X26,all!Q:Q) -> 0 | AA26: =SUMIF(all!I:I,processed!X26,all!L:L) -> 0 | AB26: =SUMIF(all!I:I,processed!X26,all!K:K) -> 0 | AG26: 沈阳局 | AH26: 长春段 | AI26: =COUNTIF(all!S$3:S$1003,AH26) -> 2 | AJ26: =AI26 -> 2 | AK26: =SUMIF(all!S:S,processed!AH26,all!Q:Q) -> 0.11805556 | AL26: =AK26 -> 0.11805556 | AM26: =SUMIF(all!S:S,processed!AH26,all!L:L) -> 410 | AN26: =AM26 -> 410 | AO26: =SUMIF(all!S:S,processed!AH26,all!K:K) -> 123 | AP26: =AO26 -> 123 | AQ26: =AO26/AM26 -> 0.3 | AR26: =AP26/AN26 -> 0.3 | AS26: =AM26/(AK26*24) -> 144.70588 | AT26: =AN26/(AL26*24) -> 144.70588
B27: 虎门 | C27: =COUNTIF(all!D$3:D$1003,B27) -> 1 | D27: 肇庆 | E27: =COUNTIF(all!E$3:E$1003,D27) -> 1 | F27: 虎门 | G27: =H27+I27 -> 3 | H27: =SUMIF(B:B,F27,C:C) -> 1 | I27: =SUMIF(D:D,F27,E:E) -> 2 | K27: CRH6A | L27: =COUNTIF(all!H$3:H$1003,K27) -> 3 | M27: =SUMIF(all!H:H,processed!K27,all!Q:Q) -> 0.090277778 | N27: =SUMIF(all!H:H,processed!K27,all!L:L) -> 194 | O27: =SUMIF(all!H:H,processed!K27,all!K:K) -> 124 | P27: =O27/N27 -> 0.63917526 | Q27: =N27/(M27*24) -> 89.538462 | S27: 沪昆线 | T27: =COUNTIF(detailed_route!F:AJ,processed!S27) -> 3 | U27: =SUMIF(detailed_route_test!A:A,processed!S27,detailed_route_test!B:B) -> 72 | X27: 二等卧 | Y27: =COUNTIF(all!I$3:I$1003,X27) -> 0 | Z27: =SUMIF(all!I:I,processed!X27,all!Q:Q) -> 0 | AA27: =SUMIF(all!I:I,processed!X27,all!L:L) -> 0 | AB27: =SUMIF(all!I:I,processed!X27,all!K:K) -> 0
B28: 深圳东 | C28: =COUNTIF(all!D$3:D$1003,B28) -> 2 | D28: 容桂 | E28: =COUNTIF(all!E$3:E$1003,D28) -> 1 | F28: 深圳东 | G28: =H28+I28 -> 3 | H28: =SUMIF(B:B,F28,C:C) -> 2 | I28: =SUMIF(D:D,F28,E:E) -> 1 | S28: 广石线 | T28: =COUNTIF(detailed_route!F:AJ,processed!S28) -> 1 | U28: =SUMIF(detailed_route_test!A:A,processed!S28,detailed_route_test!B:B) -> 70 | X28: 动卧 | Y28: =COUNTIF(all!I$3:I$1003,X28) -> 0 | Z28: =SUMIF(all!I:I,processed!X28,all!Q:Q) -> 0 | AA28: =SUMIF(all!I:I,processed!X28,all!L:L) -> 0 | AB28: =SUMIF(all!I:I,processed!X28,all!K:K) -> 0
B29: 贵阳北 | C29: =COUNTIF(all!D$3:D$1003,B29) -> 2 | D29: 深圳东 | E29: =COUNTIF(all!E$3:E$1003,D29) -> 1 | F29: 贵阳北 | G29: =H29+I29 -> 4 | H29: =SUMIF(B:B,F29,C:C) -> 2 | I29: =SUMIF(D:D,F29,E:E) -> 2 | S29: 齐北线 | T29: =COUNTIF(detailed_route!F:AJ,processed!S29) -> 1 | U29: =SUMIF(detailed_route_test!A:A,processed!S29,detailed_route_test!B:B) -> 63 | X29: 无座 | Y29: =COUNTIF(all!I$3:I$1003,X29) -> 2 | Z29: =SUMIF(all!I:I,processed!X29,all!Q:Q) -> 0.12013889 | AA29: =SUMIF(all!I:I,processed!X29,all!L:L) -> 337 | AB29: =SUMIF(all!I:I,processed!X29,all!K:K) -> 229.5 | AC29: =AB29/AA29 -> 0.6810089 | AD29: =AA29/(Z29*24) -> 116.87861
B30: 都匀东 | C30: =COUNTIF(all!D$3:D$1003,B30) -> 1 | D30: 贵阳北 | E30: =COUNTIF(all!E$3:E$1003,D30) -> 2 | F30: 都匀东 | G30: =H30+I30 -> 1 | H30: =SUMIF(B:B,F30,C:C) -> 1 | I30: =SUMIF(D:D,F30,E:E) -> 0 | S30: 江门线 | T30: =COUNTIF(detailed_route!F:AJ,processed!S30) -> 2 | U30: =SUMIF(detailed_route_test!A:A,processed!S30,detailed_route_test!B:B) -> 60
B31: 深圳 | C31: =COUNTIF(all!D$3:D$1003,B31) -> 1 | D31: 荔波 | E31: =COUNTIF(all!E$3:E$1003,D31) -> 1 | F31: 深圳 | G31: =H31+I31 -> 1 | H31: =SUMIF(B:B,F31,C:C) -> 1 | I31: =SUMIF(D:D,F31,E:E) -> 0 | S31: 莞塘深联络线 | T31: =COUNTIF(detailed_route!F:AJ,processed!S31) -> 22 | U31: =SUMIF(detailed_route_test!A:A,processed!S31,detailed_route_test!B:B) -> 44
B32: 清远 | C32: =COUNTIF(all!D$3:D$1003,B32) -> 1 | D32: 盘州 | E32: =COUNTIF(all!E$3:E$1003,D32) -> 1 | F32: 清远 | G32: =H32+I32 -> 1 | H32: =SUMIF(B:B,F32,C:C) -> 1 | I32: =SUMIF(D:D,F32,E:E) -> 0 | S32: 沪宁高速线/京沪线 | T32: =COUNTIF(detailed_route!F:AJ,processed!S32) -> 1 | U32: =SUMIF(detailed_route_test!A:A,processed!S32,detailed_route_test!B:B) -> 42
B33: 香港西九龙 | C33: =COUNTIF(all!D$3:D$1003,B33) -> 1 | D33: 韶关东 | E33: =COUNTIF(all!E$3:E$1003,D33) -> 1 | F33: 香港西九龙 | G33: =H33+I33 -> 3 | H33: =SUMIF(B:B,F33,C:C) -> 1 | I33: =SUMIF(D:D,F33,E:E) -> 2 | S33: 成昆铁路元昆段 | T33: =COUNTIF(detailed_route!F:AJ,processed!S33) -> 1 | U33: =SUMIF(detailed_route_test!A:A,processed!S33,detailed_route_test!B:B) -> 32
B34: 万宁 | C34: =COUNTIF(all!D$3:D$1003,B34) -> 1 | D34: 香港西九龙 | E34: =COUNTIF(all!E$3:E$1003,D34) -> 2 | F34: 万宁 | G34: =H34+I34 -> 1 | H34: =SUMIF(B:B,F34,C:C) -> 1 | I34: =SUMIF(D:D,F34,E:E) -> 0 | S34: 渝贵线 | T34: =COUNTIF(detailed_route!F:AJ,processed!S34) -> 3 | U34: =SUMIF(detailed_route_test!A:A,processed!S34,detailed_route_test!B:B) -> 30
B35: 长白山 | C35: =COUNTIF(all!D$3:D$1003,B35) -> 1 | D35: 海口东 | E35: =COUNTIF(all!E$3:E$1003,D35) -> 1 | F35: 长白山 | G35: =H35+I35 -> 1 | H35: =SUMIF(B:B,F35,C:C) -> 1 | I35: =SUMIF(D:D,F35,E:E) -> 0 | S35: 鹰厦线 | T35: =COUNTIF(detailed_route!F:AJ,processed!S35) -> 1 | U35: =SUMIF(detailed_route_test!A:A,processed!S35,detailed_route_test!B:B) -> 26
B36: 长春 | C36: =COUNTIF(all!D$3:D$1003,B36) -> 1 | D36: 长春 | E36: =COUNTIF(all!E$3:E$1003,D36) -> 1 | F36: 长春 | G36: =H36+I36 -> 2 | H36: =SUMIF(B:B,F36,C:C) -> 1 | I36: =SUMIF(D:D,F36,E:E) -> 1 | S36: 龙老联络线 | T36: =COUNTIF(detailed_route!F:AJ,processed!S36) -> 3 | U36: =SUMIF(detailed_route_test!A:A,processed!S36,detailed_route_test!B:B) -> 21
D37: 龙嘉 | E37: =COUNTIF(all!E$3:E$1003,D37) -> 1 | F37: 昆明 | G37: =H37+I37 -> 1 | H37: =SUMIF(B:B,F37,C:C) -> 0 | I37: =SUMIF(D:D,F37,E:E) -> 1 | S37: 平湖联络线 | T37: =COUNTIF(detailed_route!F:AJ,processed!S37) -> 2 | U37: =SUMIF(detailed_route_test!A:A,processed!S37,detailed_route_test!B:B) -> 16
F38: 厦门 | G38: =H38+I38 -> 1 | H38: =SUMIF(B:B,F38,C:C) -> 0 | I38: =SUMIF(D:D,F38,E:E) -> 1 | S38: 白敦联络线 | T38: =COUNTIF(detailed_route!F:AJ,processed!S38) -> 1 | U38: =SUMIF(detailed_route_test!A:A,processed!S38,detailed_route_test!B:B) -> 12
F39: 惠东南 | G39: =H39+I39 -> 1 | H39: =SUMIF(B:B,F39,C:C) -> 0 | I39: =SUMIF(D:D,F39,E:E) -> 1
F40: 阳澄湖 | G40: =H40+I40 -> 1 | H40: =SUMIF(B:B,F40,C:C) -> 0 | I40: =SUMIF(D:D,F40,E:E) -> 1
F41: 南京 | G41: =H41+I41 -> 1 | H41: =SUMIF(B:B,F41,C:C) -> 0 | I41: =SUMIF(D:D,F41,E:E) -> 1
...

Sheet rank
A1: 火车站 | B1: 总 | C1: 出发 | D1: 终到 | E1: 中转 | F1: 途径 | G1: 出发(raw) | H1: 终到(raw) | I1: 总数(raw)
A2: 深圳北 | B2: =C2+D2+E2 -> 30 | C2: 18 | D2: 12 | E2: 0 | G2: =SUMIF(processed!B:B,A2,processed!C:C) -> 18 | H2: =SUMIF(processed!D:D,A2,processed!E:E) -> 14 | I2: =G2+H2 -> 32
A3: 东莞 | B3: =C3+D3+E3 -> 29 | C3: 12 | D3: 17 | E3: 0 | G3: =SUMIF(processed!B:B,A3,processed!C:C) -> 14 | H3: =SUMIF(processed!D:D,A3,processed!E:E) -> 17 | I3: =G3+H3 -> 31
A4: 广州南 | B4: =C4+D4+E4 -> 5 | C4: 1 | D4: 1 | E4: 3 | G4: =SUMIF(processed!B:B,A4,processed!C:C) -> 3 | H4: =SUMIF(processed!D:D,A4,processed!E:E) -> 4 | I4: =G4+H4 -> 7
A5: 虎门 | B5: =C5+D5+E5 -> 3 | C5: 1 | D5: 2 | E5: 0 | G5: =SUMIF(processed!B:B,A5,processed!C:C) -> 1 | H5: =SUMIF(processed!D:D,A5,processed!E:E) -> 2 | I5: =G5+H5 -> 3
A6: 香港西九龙 | B6: =C6+D6+E6 -> 3 | C6: 1 | D6: 2 | E6: 0 | G6: =SUMIF(processed!B:B,A6,processed!C:C) -> 1 | H6: =SUMIF(processed!D:D,A6,processed!E:E) -> 2 | I6: =G6+H6 -> 3
A7: 阳春 | B7: =C7+D7+E7 -> 3 | C7: 1 | D7: 2 | E7: 0 | G7: =SUMIF(processed!B:B,A7,processed!C:C) -> 1 | H7: =SUMIF(processed!D:D,A7,processed!E:E) -> 2 | I7: =G7+H7 -> 3
A8: 深圳东 | B8: =C8+D8+E8 -> 3 | C8: 2 | D8: 1 | E8: 0 | G8: =SUMIF(processed!B:B,A8,processed!C:C) -> 2 | H8: =SUMIF(processed!D:D,A8,processed!E:E) -> 1 | I8: =G8+H8 -> 3
A9: 苏州 | B9: =C9+D9+E9 -> 3 | C9: 2 | D9: 1 | E9: 0 | G9: =SUMIF(processed!B:B,A9,processed!C:C) -> 2 | H9: =SUMIF(processed!D:D,A9,processed!E:E) -> 1 | I9: =G9+H9 -> 3
A10: 贵阳北 | B10: =C10+D10+E10 -> 3 | C10: 1 | D10: 1 | E10: 1 | G10: =SUMIF(processed!B:B,A10,processed!C:C) -> 2 | H10: =SUMIF(processed!D:D,A10,processed!E:E) -> 2 | I10: =G10+H10 -> 4
A11: 广州 | B11: =C11+D11+E11 -> 3 | C11: 1 | D11: 0 | E11: 2 | G11: =SUMIF(processed!B:B,A11,processed!C:C) -> 3 | H11: =SUMIF(processed!D:D,A11,processed!E:E) -> 1 | I11: =G11+H11 -> 4
A12: 东莞南 | B12: =C12+D12+E12 -> 2 | C12: 1 | D12: 1 | E12: 0 | G12: =SUMIF(processed!B:B,A12,processed!C:C) -> 1 | H12: =SUMIF(processed!D:D,A12,processed!E:E) -> 1 | I12: =G12+H12 -> 2
A13: 哈尔滨 | B13: =C13+D13+E13 -> 2 | C13: 1 | D13: 1 | E13: 0 | G13: =SUMIF(processed!B:B,A13,processed!C:C) -> 1 | H13: =SUMIF(processed!D:D,A13,processed!E:E) -> 1 | I13: =G13+H13 -> 2
... A46: 茂名 | B46: =C46+D46+E46 -> 1 | C46: 0 | D46: 0 | E46: 1 | G46: =SUMIF(processed!B:B,A46,processed!C:C) -> 1 | H46: =SUMIF(processed!D:D,A46,processed!E:E) -> 1 | I46: =G46+H46 -> 2
A47: 恩平 | B47: =C47+D47+E47 -> 0 | C47: 0 | D47: 0 | E47: 0 | F47: 1 | G47: =SUMIF(processed!B:B,A47,processed!C:C) -> 1 | H47: =SUMIF(processed!D:D,A47,processed!E:E) -> 1 | I47: =G47+H47 -> 2
A48: 加格达奇 | B48: =C48+D48+E48 -> 0 | C48: 0 | D48: 0 | E48: 0 | F48: 1 | G48: =SUMIF(processed!B:B,A48,processed!C:C) -> 1 | H48: =SUMIF(processed!D:D,A48,processed!E:E) -> 1 | I48: =G48+H48 -> 2
A49: 江门 | B49: =C49+D49+E49 -> 0 | C49: 0 | D49: 0 | E49: 0 | F49: 1 | G49: =SUMIF(processed!B:B,A49,processed!C:C) -> 1 | H49: =SUMIF(processed!D:D,A49,processed!E:E) -> 1 | I49: =G49+H49 -> 2

Sheet detailed_route
A1: 始发站 | B1: 终到站 | C1: 总里程 | D1: 站点和里程
F2: =COUNTA(F3:F9999) -> 69 | H2: =COUNTA(H3:H9999) -> 69 | K2: =COUNTA(K3:K9999) -> 69 | M2: =COUNTA(M3:M9999) -> 38 | P2: =COUNTA(P3:P9999) -> 38 | R2: =COUNTA(R3:R9999) -> 32 | U2: =COUNTA(U3:U9999) -> 32 | W2: =COUNTA(W3:W9999) -> 24 | Z2: =COUNTA(Z3:Z9999) -> 24 | AB2: =COUNTA(AB3:AB9999) -> 1 | AE2: =COUNTA(AE3:AE9999) -> 1
A3: 大理 | B3: 昆明 | C3: 328km | D3: 大理-楚大线175km-广通北-广昆线广温段121km-温泉-成昆铁路元昆段32km-昆明 | F3: 大理 | G3: ⇌ | H3: 楚大线 | I3: 175km | J3: ⇌ | K3: 广通北 | L3: ⇌ | M3: 广昆线广温段 | N3: 121km | O3: ⇌ | P3: 温泉 | Q3: ⇌ | R3: 成昆铁路元昆段 | S3: 32km | T3: ⇌ | U3: 昆明
A4: 东莞 | B4: 厦门 | C4: 575km | D4: 东莞-广九线56km-平湖-平湖联络线8km-李朗所-杭深线485km-前场-鹰厦线26km-厦门 | F4: 东莞 | G4: ⇌ | H4: 广九线 | I4: 56km | J4: ⇌ | K4: 平湖 | L4: ⇌ | M4: 平湖联络线 | N4: 8km | O4: ⇌ | P4: 李朗所 | Q4: ⇌ | R4: 杭深线 | S4: 485km | T4: ⇌ | U4: 前场 | V4: ⇌ | W4: 鹰厦线 | X4: 26km | Y4: ⇌ | Z4: 厦门
A5: 厦门北 | B5: 东莞 | C5: 526km | D5: 厦门北-杭深线498km-李朗所-平湖联络线8km-平湖-广九线56km-东莞 | F5: 厦门北 | G5: ⇌ | H5: 杭深线 | I5: 498km | J5: ⇌ | K5: 李朗所 | L5: ⇌ | M5: 平湖联络线 | N5: 8km | O5: ⇌ | P5: 平湖 | Q5: ⇌ | R5: 广九线 | S5: 56km | T5: ⇌ | U5: 东莞
A6: 东莞 | B6: 东莞南 | C6: 39km | D6: 东莞-广九线37km-塘厦所-莞塘深联络线2km-东莞南 | F6: 东莞 | G6: ⇌ | H6: 广九线 | I6: 37km | J6: ⇌ | K6: 塘厦所 | L6: ⇌ | M6: 莞塘深联络线 | N6: 2km | O6: ⇌ | P6: 东莞南
A7: 东莞南 | B7: 东莞 | C7: 39km | D7: 东莞南-莞塘深联络线2km-塘厦所-广九线37km-东莞 | F7: 东莞南 | G7: ⇌ | H7: 莞塘深联络线 | I7: 2km | J7: ⇌ | K7: 塘厦所 | L7: ⇌ | M7: 广九线 | N7: 37km | O7: ⇌ | P7: 东莞
A8: 深圳北 | B8: 东莞 | C8: 74km | D8: 深圳北-广深港高速线16km-光明城-京港高铁赣深段19km-东莞南-莞塘深联络线2km-塘厦所-广九线37km-东莞 | F8: 深圳北 | G8: ⇌ | H8: 广深港高速线 | I8: 16km | J8: ⇌ | K8: 光明城 | L8: ⇌ | M8: 京港高铁赣深段 | N8: 19km | O8: ⇌ | P8: 东莞南 | Q8: ⇌ | R8: 莞塘深联络线 | S8: 2km | T8: ⇌ | U8: 塘厦所 | V8: ⇌ | W8: 广九线 | X8: 37km | Y8: ⇌ | Z8: 东莞
A9: 东莞 | B9: 深圳北 | C9: 74km | D9: 东莞-广九线37km-塘厦所-莞塘深联络线2km-东莞南-京港高铁赣深段19km-光明城-广深港高速线16km-深圳北 | F9: 东莞 | G9: ⇌ | H9: 广九线 | I9: 37km | J9: ⇌ | K9: 塘厦所 | L9: ⇌ | M9: 莞塘深联络线 | N9: 2km | O9: ⇌ | P9: 东莞南 | Q9: ⇌ | R9: 京港高铁赣深段 | S9: 19km | T9: ⇌ | U9: 光明城 | V9: ⇌ | W9: 广深港高速线 | X9: 16km | Y9: ⇌ | Z9: 深圳北
A10: 深圳北 | B10: 东莞 | C10: 74km | D10: 深圳北-广深港高速线16km-光明城-京港高铁赣深段19km-东莞南-莞塘深联络线2km-塘厦所-广九线37km-东莞 | F10: 深圳北 | G10: ⇌ | H10: 广深港高速线 | I10: 16km | J10: ⇌ | K10: 光明城 | L10: ⇌ | M10: 京港高铁赣深段 | N10: 19km | O10: ⇌ | P10: 东莞南 | Q10: ⇌ | R10: 莞塘深联络线 | S10: 2km | T10: ⇌ | U10: 塘厦所 | V10: ⇌ | W10: 广九线 | X10: 37km | Y10: ⇌ | Z10: 东莞
A11: 东莞 | B11: 深圳北 | C11: 74km | D11: 东莞-广九线37km-塘厦所-莞塘深联络线2km-东莞南-京港高铁赣深段19km-光明城-广深港高速线16km-深圳北 | F11: 东莞 | G11: ⇌ | H11: 广九线 | I11: 37km | J11: ⇌ | K11: 塘厦所 | L11: ⇌ | M11: 莞塘深联络线 | N11: 2km | O11: ⇌ | P11: 东莞南 | Q11: ⇌ | R11: 京港高铁赣深段 | S11: 19km | T11: ⇌ | U11: 光明城 | V11: ⇌ | W11: 广深港高速线 | X11: 16km | Y11: ⇌ | Z11: 深圳北
A12: 深圳北 | B12: 东莞 | C12: 74km | D12: 深圳北-广深港高速线16km-光明城-京港高铁赣深段19km-东莞南-莞塘深联络线2km-塘厦所-广九线37km-东莞 | F12: 深圳北 | G12: ⇌ | H12: 广深港高速线 | I12: 16km | J12: ⇌ | K12: 光明城 | L12: ⇌ | M12: 京港高铁赣深段 | N12: 19km | O12: ⇌ | P12: 东莞南 | Q12: ⇌ | R12: 莞塘深联络线 | S12: 2km | T12: ⇌ | U12: 塘厦所 | V12: ⇌ | W12: 广九线 | X12: 37km | Y12: ⇌ | Z12: 东莞
A13: 深圳北 | B13: 东莞 | C13: 74km | D13: 深圳北-广深港高速线16km-光明城-京港高铁赣深段19km-东莞南-莞塘深联络线2km-塘厦所-广九线37km-东莞 | F13: 深圳北 | G13: ⇌ | H13: 广深港高速线 | I13: 16km | J13: ⇌ | K13: 光明城 | L13: ⇌ | M13: 京港高铁赣深段 | N13: 19km | O13: ⇌ | P13: 东莞南 | Q13: ⇌ | R13: 莞塘深联络线 | S13: 2km | T13: ⇌ | U13: 塘厦所 | V13: ⇌ | W13: 广九线 | X13: 37km | Y13: ⇌ | Z13: 东莞
A14: 东莞 | B14: 深圳北 | C14: 74km | D14: 东莞-广九线37km-塘厦所-莞塘深联络线2km-东莞南-京港高铁赣深段19km-光明城-广深港高速线16km-深圳北 | F14: 东莞 | G14: ⇌ | H14: 广九线 | I14: 37km | J14: ⇌ | K14: 塘厦所 | L14: ⇌ | M14: 莞塘深联络线 | N14: 2km | O14: ⇌ | P14: 东莞南 | Q14: ⇌ | R14: 京港高铁赣深段 | S14: 19km | T14: ⇌ | U14: 光明城 | V14: ⇌ | W14: 广深港高速线 | X14: 16km | Y14: ⇌ | Z14: 深圳北
A15: 深圳北 | B15: 惠东南 | C15: 88km | D15: 深圳北-杭深线88km-惠东 | F15: 深圳北 | G15: ⇌ | H15: 杭深线 | I15: 88km | J15: ⇌ | K15: 惠东南
A16: 无锡新区 | B16: 苏州 | C16: 29km | D16: 无锡新区-沪宁高速线29km-苏州 | F16: 无锡新区 | G16: ⇌ | H16: 沪宁高速线 | I16: 29km | J16: ⇌ | K16: 苏州
A17: 苏州 | B17: 阳澄湖 | C17: 25km | D17: 苏州-沪宁高速线25km-阳澄湖 | F17: 苏州 | G17: ⇌ | H17: 沪宁高速线 | I17: 25km | J17: ⇌ | K17: 阳澄湖
A18: 苏州 | B18: 无锡 | C18: 42km | D18: 苏州-沪宁高速线/京沪线42km-无锡 | F18: 苏州 | G18: ⇌ | H18: 沪宁高速线/京沪线 | I18: 42km | J18: ⇌ | K18: 无锡
A19: 无锡 | B19: 南京 | C19: 174km | D19: 无锡-京沪线83km-丹阳-沪宁高速线27km-镇江-京沪线64km-南京 | F19: 无锡 | G19: ⇌ | H19: 京沪线 | I19: 83km | J19: ⇌ | K19: 丹阳 | L19: ⇌ | M19: 沪宁高速线 | N19: 27km | O19: ⇌ | P19: 镇江 | Q19: ⇌ | R19: 京沪线 | S19: 64km | T19: ⇌ | U19: 南京
A20: 深圳北 | B20: 长沙南 | C20: 809km | D20: 深圳北-广深港高速线102km-广州南-京广高铁707km-长沙南 | F20: 深圳北 | G20: ⇌ | H20: 广深港高速线 | I20: 102km | J20: ⇌ | K20: 广州南 | L20: ⇌ | M20: 京广高铁 | N20: 707km | O20: ⇌ | P20: 长沙南
A21: 长沙南 | B21: 深圳北 | C21: 809km | D21: 长沙南-京广高铁707km-广州南-广深港高速线102km-深圳北 | F21: 长沙南 | G21: ⇌ | H21: 京广高铁 | I21: 707km | J21: ⇌ | K21: 广州南 | L21: ⇌ | M21: 广深港高速线 | N21: 102km | O21: ⇌ | P21: 深圳北
A22: 深圳北 | B22: 东莞 | C22: 74km | D22: 深圳北-广深港高速线16km-光明城-京港高铁赣深段19km-东莞南-莞塘深联络线2km-塘厦所-广九线37km-东莞 | F22: 深圳北 | G22: ⇌ | H22: 广深港高速线 | I22: 16km | J22: ⇌ | K22: 光明城 | L22: ⇌ | M22: 京港高铁赣深段 | N22: 19km | O22: ⇌ | P22: 东莞南 | Q22: ⇌ | R22: 莞塘深联络线 | S22: 2km | T22: ⇌ | U22: 塘厦所 | V22: ⇌ | W22: 广九线 | X22: 37km | Y22: ⇌ | Z22: 东莞
A23: 东莞 | B23: 广州 | C23: 71km | D23: 东莞-广九线71km-广州 | F23: 东莞 | G23: ⇌ | H23: 广九线 | I23: 71km | J23: ⇌ | K23: 广州
A24: 广州 | B24: 阳春 | C24: 246km | D24: 广州-广茂线246km-阳春 | F24: 广州 | G24: ⇌ | H24: 广茂线 | I24: 246km | J24: ⇌ | K24: 阳春
A25: 阳江 | B25: 江门 | C25: 148km | D25: 阳江-深湛线江湛段148km-江门 | F25: 阳江 | G25: ⇌ | H25: 深湛线江湛段 | I25: 148km | J25: ⇌ | K25: 江门
A26: 江门 | B26: 深圳北 | C26: 177km | D26: 江门-江门线30km-小榄-广珠城际线45km-广州南-广深港高速线102km-深圳北 | F26: 江门 | G26: ⇌ | H26: 江门线 | I26: 30km | J26: ⇌ | K26: 小榄 | L26: ⇌ | M26: 广珠城际线 | N26: 45km | O26: ⇌ | P26: 广州南 | Q26: ⇌ | R26: 广深港高速线 | S26: 102km | T26: ⇌ | U26: 深圳北
A27: 深圳北 | B27: 东莞 | C27: 74km | D27: 深圳北-广深港高速线16km-光明城-京港高铁赣深段19km-东莞南-莞塘深联络线2km-塘厦所-广九线37km-东莞 | F27: 深圳北 | G27: ⇌ | H27: 广深港高速线 | I27: 16km | J27: ⇌ | K27: 光明城 | L27: ⇌ | M27: 京港高铁赣深段 | N27: 19km | O27: ⇌ | P27: 东莞南 | Q27: ⇌ | R27: 莞塘深联络线 | S27: 2km | T27: ⇌ | U27: 塘厦所 | V27: ⇌ | W27: 广九线 | X27: 37km | Y27: ⇌ | Z27: 东莞
A28: 东莞 | B28: 深圳北 | C28: 74km | D28: 东莞-广九线37km-塘厦所-莞塘深联络线2km-东莞南-京港高铁赣深段19km-光明城-广深港高速线16km-深圳北 | F28: 东莞 | G28: ⇌ | H28: 广九线 | I28: 37km | J28: ⇌ | K28: 塘厦所 | L28: ⇌ | M28: 莞塘深联络线 | N28: 2km | O28: ⇌ | P28: 东莞南 | Q28: ⇌ | R28: 京港高铁赣深段 | S28: 19km | T28: ⇌ | U28: 光明城 | V28: ⇌ | W28: 广深港高速线 | X28: 16km | Y28: ⇌ | Z28: 深圳北
A29: 深圳北 | B29: 东莞 | C29: 74km | D29: 深圳北-广深港高速线16km-光明城-京港高铁赣深段19km-东莞南-莞塘深联络线2km-塘厦所-广九线37km-东莞 | F29: 深圳北 | G29: ⇌ | H29: 广深港高速线 | I29: 16km | J29: ⇌ | K29: 光明城 | L29: ⇌ | M29: 京港高铁赣深段 | N29: 19km | O29: ⇌ | P29: 东莞南 | Q29: ⇌ | R29: 莞塘深联络线 | S29: 2km | T29: ⇌ | U29: 塘厦所 | V29: ⇌ | W29: 广九线 | X29: 37km | Y29: ⇌ | Z29: 东莞
A30: 东莞 | B30: 深圳北 | C30: 74km | D30: 东莞-广九线37km-塘厦所-莞塘深联络线2km-东莞南-京港高铁赣深段19km-光明城-广深港高速线16km-深圳北 | F30: 东莞 | G30: ⇌ | H30: 广九线 | I30: 37km | J30: ⇌ | K30: 塘厦所 | L30: ⇌ | M30: 莞塘深联络线 | N30: 2km | O30: ⇌ | P30: 东莞南 | Q30: ⇌ | R30: 京港高铁赣深段 | S30: 19km | T30: ⇌ | U30: 光明城 | V30: ⇌ | W30: 广深港高速线 | X30: 16km | Y30: ⇌ | Z30: 深圳北
A31: 深圳北 | B31: 虎门 | C31: 52km | D31: 深圳北-广深港高速线52km-虎门 | F31: 深圳北 | G31: ⇌ | H31: 广深港高速线 | I31: 52km | J31: ⇌ | K31: 虎门
A32: 阳春 | B32: 茂名 | C32: 115km | D32: 阳春-广茂线115km-茂名 | F32: 阳春 | G32: ⇌ | H32: 广茂线 | I32: 115km | J32: ⇌ | K32: 茂名
A33: 茂名 | B33: 恩平 | C33: 180km | D33: 茂名-深湛线江湛段180km-恩平 | F33: 茂名 | G33: ⇌ | H33: 深湛线江湛段 | I33: 180km | J33: ⇌ | K33: 恩平
A34: 恩平 | B34: 广州南 | C34: 160km | D34: 恩平-深湛线江湛段85km-江门-江门线30km-小榄-广珠城际线45km-广州南 | F34: 恩平 | G34: ⇌ | H34: 深湛线江湛段 | I34: 85km | J34: ⇌ | K34: 江门 | L34: ⇌ | M34: 江门线 | N34: 30km | O34: ⇌ | P34: 小榄 | Q34: ⇌ | R34: 广珠城际线 | S34: 45km | T34: ⇌ | U34: 广州南
A35: 广州 | B35: 东莞 | C35: 71km | D35: 广州-广九线71km-东莞 | F35: 广州 | G35: ⇌ | H35: 广九线 | I35: 71km | J35: ⇌ | K35: 东莞
A36: 亚布力西 | B36: 哈尔滨 | C36: 204km | D36: 亚布力西-哈牡客专线204km-哈尔滨 | F36: 亚布力西 | G36: ⇌ | H36: 哈牡客专线 | I36: 204km | J36: ⇌ | K36: 哈尔滨
